2019-08-07 21:09:09,837 - octoprint.plugins.portlister - WARNING - Not auto connecting because printer is not closed nor in error state.
2019-08-07 21:09:09,848 - octoprint.plugins.portlister - WARNING - Not auto connecting because printer is not closed nor in error state.
2019-08-07 21:12:27,890 - octoprint.server.util.sockjs - INFO - New connection from client: 192.168.10.10
2019-08-07 21:12:30,780 - octoprint.plugins.announcements - ERROR - Could not fetch channel _important from http://octoprint.org/feeds/important.xml: ('Connection aborted.', gaierror(-2, 'Name or service not known'))
Traceback (most recent call last):
  File "/usr/lib/python2.7/site-packages/octoprint/plugins/announcements/__init__.py", line 269, in _get_channel_data_from_network
    r = requests.get(url)
  File "/usr/lib/python2.7/site-packages/requests/api.py", line 69, in get
    return request('get', url, params=params, **kwargs)
  File "/usr/lib/python2.7/site-packages/requests/api.py", line 50, in request
    response = session.request(method=method, url=url, **kwargs)
  File "/usr/lib/python2.7/site-packages/requests/sessions.py", line 465, in request
    resp = self.send(prep, **send_kwargs)
  File "/usr/lib/python2.7/site-packages/requests/sessions.py", line 573, in send
    r = adapter.send(request, **kwargs)
  File "/usr/lib/python2.7/site-packages/requests/adapters.py", line 415, in send
    raise ConnectionError(err, request=request)
ConnectionError: ('Connection aborted.', gaierror(-2, 'Name or service not known'))
2019-08-07 21:12:30,831 - octoprint.plugins.softwareupdate - ERROR - Could not check active_filters for updates
Traceback (most recent call last):
  File "/usr/lib/python2.7/site-packages/octoprint/plugins/softwareupdate/__init__.py", line 482, in _get_current_version
    information, is_current = version_checker.get_latest(target, check)
  File "/usr/lib/python2.7/site-packages/octoprint/plugins/softwareupdate/version_checks/github_release.py", line 134, in get_latest
    include_prerelease=include_prerelease)
  File "/usr/lib/python2.7/site-packages/octoprint/plugins/softwareupdate/version_checks/github_release.py", line 19, in _get_latest_release
    r = requests.get(RELEASE_URL.format(user=user, repo=repo))
  File "/usr/lib/python2.7/site-packages/requests/api.py", line 69, in get
    return request('get', url, params=params, **kwargs)
  File "/usr/lib/python2.7/site-packages/requests/api.py", line 50, in request
    response = session.request(method=method, url=url, **kwargs)
  File "/usr/lib/python2.7/site-packages/requests/sessions.py", line 465, in request
    resp = self.send(prep, **send_kwargs)
  File "/usr/lib/python2.7/site-packages/requests/sessions.py", line 573, in send
    r = adapter.send(request, **kwargs)
  File "/usr/lib/python2.7/site-packages/requests/adapters.py", line 415, in send
    raise ConnectionError(err, request=request)
ConnectionError: ('Connection aborted.', gaierror(-2, 'Name or service not known'))
2019-08-07 21:12:30,854 - octoprint.plugins.softwareupdate - ERROR - Could not check touchui for updates
Traceback (most recent call last):
  File "/usr/lib/python2.7/site-packages/octoprint/plugins/softwareupdate/__init__.py", line 482, in _get_current_version
    information, is_current = version_checker.get_latest(target, check)
  File "/usr/lib/python2.7/site-packages/octoprint/plugins/softwareupdate/version_checks/github_release.py", line 134, in get_latest
    include_prerelease=include_prerelease)
  File "/usr/lib/python2.7/site-packages/octoprint/plugins/softwareupdate/version_checks/github_release.py", line 19, in _get_latest_release
    r = requests.get(RELEASE_URL.format(user=user, repo=repo))
  File "/usr/lib/python2.7/site-packages/requests/api.py", line 69, in get
    return request('get', url, params=params, **kwargs)
  File "/usr/lib/python2.7/site-packages/requests/api.py", line 50, in request
    response = session.request(method=method, url=url, **kwargs)
  File "/usr/lib/python2.7/site-packages/requests/sessions.py", line 465, in request
    resp = self.send(prep, **send_kwargs)
  File "/usr/lib/python2.7/site-packages/requests/sessions.py", line 573, in send
    r = adapter.send(request, **kwargs)
  File "/usr/lib/python2.7/site-packages/requests/adapters.py", line 415, in send
    raise ConnectionError(err, request=request)
ConnectionError: ('Connection aborted.', gaierror(-2, 'Name or service not known'))
2019-08-07 21:12:30,867 - octoprint.plugins.softwareupdate - ERROR - Could not check customcontrol for updates
Traceback (most recent call last):
  File "/usr/lib/python2.7/site-packages/octoprint/plugins/softwareupdate/__init__.py", line 482, in _get_current_version
    information, is_current = version_checker.get_latest(target, check)
  File "/usr/lib/python2.7/site-packages/octoprint/plugins/softwareupdate/version_checks/github_release.py", line 134, in get_latest
    include_prerelease=include_prerelease)
  File "/usr/lib/python2.7/site-packages/octoprint/plugins/softwareupdate/version_checks/github_release.py", line 19, in _get_latest_release
    r = requests.get(RELEASE_URL.format(user=user, repo=repo))
  File "/usr/lib/python2.7/site-packages/requests/api.py", line 69, in get
    return request('get', url, params=params, **kwargs)
  File "/usr/lib/python2.7/site-packages/requests/api.py", line 50, in request
    response = session.request(method=method, url=url, **kwargs)
  File "/usr/lib/python2.7/site-packages/requests/sessions.py", line 465, in request
    resp = self.send(prep, **send_kwargs)
  File "/usr/lib/python2.7/site-packages/requests/sessions.py", line 573, in send
    r = adapter.send(request, **kwargs)
  File "/usr/lib/python2.7/site-packages/requests/adapters.py", line 415, in send
    raise ConnectionError(err, request=request)
ConnectionError: ('Connection aborted.', gaierror(-2, 'Name or service not known'))
2019-08-07 21:12:30,881 - octoprint.plugins.softwareupdate - ERROR - Could not check portlister for updates
Traceback (most recent call last):
  File "/usr/lib/python2.7/site-packages/octoprint/plugins/softwareupdate/__init__.py", line 482, in _get_current_version
    information, is_current = version_checker.get_latest(target, check)
  File "/usr/lib/python2.7/site-packages/octoprint/plugins/softwareupdate/version_checks/github_release.py", line 134, in get_latest
    include_prerelease=include_prerelease)
  File "/usr/lib/python2.7/site-packages/octoprint/plugins/softwareupdate/version_checks/github_release.py", line 19, in _get_latest_release
    r = requests.get(RELEASE_URL.format(user=user, repo=repo))
  File "/usr/lib/python2.7/site-packages/requests/api.py", line 69, in get
    return request('get', url, params=params, **kwargs)
  File "/usr/lib/python2.7/site-packages/requests/api.py", line 50, in request
    response = session.request(method=method, url=url, **kwargs)
  File "/usr/lib/python2.7/site-packages/requests/sessions.py", line 465, in request
    resp = self.send(prep, **send_kwargs)
  File "/usr/lib/python2.7/site-packages/requests/sessions.py", line 573, in send
    r = adapter.send(request, **kwargs)
  File "/usr/lib/python2.7/site-packages/requests/adapters.py", line 415, in send
    raise ConnectionError(err, request=request)
ConnectionError: ('Connection aborted.', gaierror(-2, 'Name or service not known'))
2019-08-07 21:12:30,988 - octoprint.plugins.softwareupdate - ERROR - Could not check requestspinner for updates
Traceback (most recent call last):
  File "/usr/lib/python2.7/site-packages/octoprint/plugins/softwareupdate/__init__.py", line 482, in _get_current_version
    information, is_current = version_checker.get_latest(target, check)
  File "/usr/lib/python2.7/site-packages/octoprint/plugins/softwareupdate/version_checks/github_release.py", line 134, in get_latest
    include_prerelease=include_prerelease)
  File "/usr/lib/python2.7/site-packages/octoprint/plugins/softwareupdate/version_checks/github_release.py", line 19, in _get_latest_release
    r = requests.get(RELEASE_URL.format(user=user, repo=repo))
  File "/usr/lib/python2.7/site-packages/requests/api.py", line 69, in get
    return request('get', url, params=params, **kwargs)
  File "/usr/lib/python2.7/site-packages/requests/api.py", line 50, in request
    response = session.request(method=method, url=url, **kwargs)
  File "/usr/lib/python2.7/site-packages/requests/sessions.py", line 465, in request
    resp = self.send(prep, **send_kwargs)
  File "/usr/lib/python2.7/site-packages/requests/sessions.py", line 573, in send
    r = adapter.send(request, **kwargs)
  File "/usr/lib/python2.7/site-packages/requests/adapters.py", line 415, in send
    raise ConnectionError(err, request=request)
ConnectionError: ('Connection aborted.', gaierror(-2, 'Name or service not known'))
2019-08-07 21:12:31,002 - octoprint.plugins.softwareupdate - ERROR - Could not check cost for updates
Traceback (most recent call last):
  File "/usr/lib/python2.7/site-packages/octoprint/plugins/softwareupdate/__init__.py", line 482, in _get_current_version
    information, is_current = version_checker.get_latest(target, check)
  File "/usr/lib/python2.7/site-packages/octoprint/plugins/softwareupdate/version_checks/github_release.py", line 134, in get_latest
    include_prerelease=include_prerelease)
  File "/usr/lib/python2.7/site-packages/octoprint/plugins/softwareupdate/version_checks/github_release.py", line 19, in _get_latest_release
    r = requests.get(RELEASE_URL.format(user=user, repo=repo))
  File "/usr/lib/python2.7/site-packages/requests/api.py", line 69, in get
    return request('get', url, params=params, **kwargs)
  File "/usr/lib/python2.7/site-packages/requests/api.py", line 50, in request
    response = session.request(method=method, url=url, **kwargs)
  File "/usr/lib/python2.7/site-packages/requests/sessions.py", line 465, in request
    resp = self.send(prep, **send_kwargs)
  File "/usr/lib/python2.7/site-packages/requests/sessions.py", line 573, in send
    r = adapter.send(request, **kwargs)
  File "/usr/lib/python2.7/site-packages/requests/adapters.py", line 415, in send
    raise ConnectionError(err, request=request)
ConnectionError: ('Connection aborted.', gaierror(-2, 'Name or service not known'))
2019-08-07 21:12:31,016 - octoprint.plugins.softwareupdate - ERROR - Could not check systemcommandeditor for updates
Traceback (most recent call last):
  File "/usr/lib/python2.7/site-packages/octoprint/plugins/softwareupdate/__init__.py", line 482, in _get_current_version
    information, is_current = version_checker.get_latest(target, check)
  File "/usr/lib/python2.7/site-packages/octoprint/plugins/softwareupdate/version_checks/github_release.py", line 134, in get_latest
    include_prerelease=include_prerelease)
  File "/usr/lib/python2.7/site-packages/octoprint/plugins/softwareupdate/version_checks/github_release.py", line 19, in _get_latest_release
    r = requests.get(RELEASE_URL.format(user=user, repo=repo))
  File "/usr/lib/python2.7/site-packages/requests/api.py", line 69, in get
    return request('get', url, params=params, **kwargs)
  File "/usr/lib/python2.7/site-packages/requests/api.py", line 50, in request
    response = session.request(method=method, url=url, **kwargs)
  File "/usr/lib/python2.7/site-packages/requests/sessions.py", line 465, in request
    resp = self.send(prep, **send_kwargs)
  File "/usr/lib/python2.7/site-packages/requests/sessions.py", line 573, in send
    r = adapter.send(request, **kwargs)
  File "/usr/lib/python2.7/site-packages/requests/adapters.py", line 415, in send
    raise ConnectionError(err, request=request)
ConnectionError: ('Connection aborted.', gaierror(-2, 'Name or service not known'))
2019-08-07 21:12:31,029 - octoprint.plugins.softwareupdate - ERROR - Could not check bqappcompanion for updates
Traceback (most recent call last):
  File "/usr/lib/python2.7/site-packages/octoprint/plugins/softwareupdate/__init__.py", line 482, in _get_current_version
    information, is_current = version_checker.get_latest(target, check)
  File "/usr/lib/python2.7/site-packages/octoprint/plugins/softwareupdate/version_checks/github_release.py", line 134, in get_latest
    include_prerelease=include_prerelease)
  File "/usr/lib/python2.7/site-packages/octoprint/plugins/softwareupdate/version_checks/github_release.py", line 19, in _get_latest_release
    r = requests.get(RELEASE_URL.format(user=user, repo=repo))
  File "/usr/lib/python2.7/site-packages/requests/api.py", line 69, in get
    return request('get', url, params=params, **kwargs)
  File "/usr/lib/python2.7/site-packages/requests/api.py", line 50, in request
    response = session.request(method=method, url=url, **kwargs)
  File "/usr/lib/python2.7/site-packages/requests/sessions.py", line 465, in request
    resp = self.send(prep, **send_kwargs)
  File "/usr/lib/python2.7/site-packages/requests/sessions.py", line 573, in send
    r = adapter.send(request, **kwargs)
  File "/usr/lib/python2.7/site-packages/requests/adapters.py", line 415, in send
    raise ConnectionError(err, request=request)
ConnectionError: ('Connection aborted.', gaierror(-2, 'Name or service not known'))
2019-08-07 21:12:31,044 - octoprint.plugins.softwareupdate - ERROR - Could not check yamlpatcher for updates
Traceback (most recent call last):
  File "/usr/lib/python2.7/site-packages/octoprint/plugins/softwareupdate/__init__.py", line 482, in _get_current_version
    information, is_current = version_checker.get_latest(target, check)
  File "/usr/lib/python2.7/site-packages/octoprint/plugins/softwareupdate/version_checks/github_release.py", line 134, in get_latest
    include_prerelease=include_prerelease)
  File "/usr/lib/python2.7/site-packages/octoprint/plugins/softwareupdate/version_checks/github_release.py", line 19, in _get_latest_release
    r = requests.get(RELEASE_URL.format(user=user, repo=repo))
  File "/usr/lib/python2.7/site-packages/requests/api.py", line 69, in get
    return request('get', url, params=params, **kwargs)
  File "/usr/lib/python2.7/site-packages/requests/api.py", line 50, in request
    response = session.request(method=method, url=url, **kwargs)
  File "/usr/lib/python2.7/site-packages/requests/sessions.py", line 465, in request
    resp = self.send(prep, **send_kwargs)
  File "/usr/lib/python2.7/site-packages/requests/sessions.py", line 573, in send
    r = adapter.send(request, **kwargs)
  File "/usr/lib/python2.7/site-packages/requests/adapters.py", line 415, in send
    raise ConnectionError(err, request=request)
ConnectionError: ('Connection aborted.', gaierror(-2, 'Name or service not known'))
2019-08-07 21:12:31,159 - octoprint.plugins.softwareupdate - INFO - Saved version cache to disk
2019-08-07 21:13:02,952 - octoprint.server.api - INFO - Performing command: /home/rhradec/halt
2019-08-07 21:13:03,169 - octoprint.server.api - WARNING - Command failed with return code -15: 
2019-08-07 21:13:03,235 - octoprint.server - INFO - Shutting down...
2019-08-07 21:13:03,539 - octoprint.server - INFO - Goodbye!
2019-08-07 21:13:12,486 - octoprint.server - INFO - Starting OctoPrint 1.2.15 (HEAD -> master branch)
2019-08-07 21:13:12,515 - octoprint.plugin.core - INFO - Loading plugins from /home/rhradec/.octoprint/plugins, /usr/lib/python2.7/site-packages/octoprint/plugins and installed plugin packages...
2019-08-07 21:13:15,290 - octoprint.plugins.discovery - INFO - pybonjour is not installed, Zeroconf Discovery won't be available
2019-08-07 21:13:15,292 - octoprint.plugin.core - INFO - Found 17 plugin(s) providing 16 mixin implementations, 15 hook handlers
2019-08-07 21:13:15,304 - octoprint.filemanager.storage - INFO - Initializing the file metadata for /home/rhradec/.octoprint/uploads...
2019-08-07 21:13:15,367 - octoprint.filemanager.storage - INFO - ... file metadata for /home/rhradec/.octoprint/uploads initialized successfully.
2019-08-07 21:13:19,378 - octoprint.util.pip - INFO - Found pip at /bin/pip2, version is 8.1.2
2019-08-07 21:13:19,548 - octoprint.plugins.softwareupdate - INFO - Loaded version cache from disk
2019-08-07 21:13:19,578 - octoprint.plugin.core - INFO - Initialized 16 plugin implementation(s)
2019-08-07 21:13:20,196 - octoprint.plugin.core - INFO - 17 plugin(s) registered with the system:
|  Active Filters (0.0.1) = /usr/lib/python2.7/site-packages/octoprint_active_filters
|  Announcement Plugin (bundled) = /usr/lib/python2.7/site-packages/octoprint/plugins/announcements
|  BQ Android App Companion (0.1.1) = /usr/lib/python2.7/site-packages/octoprint_bqappcompanion
|  Cost Plugin (0.1.2) = /usr/lib/python2.7/site-packages/octoprint_cost
| !CuraEngine (<= 15.04) (bundled) = /usr/lib/python2.7/site-packages/octoprint/plugins/cura
|  Custom Control Editor (0.2.1) = /usr/lib/python2.7/site-packages/octoprint_customControl
|  Discovery (bundled) = /usr/lib/python2.7/site-packages/octoprint/plugins/discovery
|  EEPROM Marlin Editor Plugin (0.1.0) = /usr/lib/python2.7/site-packages/octoprint_eeprom_marlin
|  Plugin Manager (bundled) = /usr/lib/python2.7/site-packages/octoprint/plugins/pluginmanager
|  PortLister (0.1.5) = /usr/lib/python2.7/site-packages/octoprint_portlister
|  RequestSpinner (0.1.1) = /usr/lib/python2.7/site-packages/octoprint_requestspinner
|  ScreenSquish (0.1) = /usr/lib/python2.7/site-packages/octoprint_ScreenSquish
|  Software Update (bundled) = /usr/lib/python2.7/site-packages/octoprint/plugins/softwareupdate
|  System Command Editor (0.3.1) = /usr/lib/python2.7/site-packages/octoprint_systemcommandeditor
|  TouchUI (0.3.4) = /usr/lib/python2.7/site-packages/octoprint_touchui
|  Virtual Printer (bundled) = /usr/lib/python2.7/site-packages/octoprint/plugins/virtual_printer
|  Yamlpatcher (0.1.1) = /usr/lib/python2.7/site-packages/octoprint_yamlpatcher
2019-08-07 21:13:20,199 - octoprint.filemanager - INFO - Adding backlog items from all storage types to analysis queue...
2019-08-07 21:13:20,213 - octoprint.filemanager - INFO - Added 0 items from storage type "local" to analysis queue
2019-08-07 21:13:20,218 - octoprint.server - INFO - Reset webasset folder /home/rhradec/.octoprint/generated/webassets...
2019-08-07 21:13:20,239 - octoprint.server - INFO - Reset webasset folder /home/rhradec/.octoprint/generated/.webassets-cache...
2019-08-07 21:13:21,211 - octoprint.plugins.pluginmanager - ERROR - Could not fetch plugins from repository at http://plugins.octoprint.org/plugins.json: ('Connection aborted.', gaierror(-2, 'Name or service not known'))
Traceback (most recent call last):
  File "/usr/lib/python2.7/site-packages/octoprint/plugins/pluginmanager/__init__.py", line 542, in _fetch_repository_from_url
    r = requests.get(repository_url)
  File "/usr/lib/python2.7/site-packages/requests/api.py", line 69, in get
    return request('get', url, params=params, **kwargs)
  File "/usr/lib/python2.7/site-packages/requests/api.py", line 50, in request
    response = session.request(method=method, url=url, **kwargs)
  File "/usr/lib/python2.7/site-packages/requests/sessions.py", line 465, in request
    resp = self.send(prep, **send_kwargs)
  File "/usr/lib/python2.7/site-packages/requests/sessions.py", line 573, in send
    r = adapter.send(request, **kwargs)
  File "/usr/lib/python2.7/site-packages/requests/adapters.py", line 415, in send
    raise ConnectionError(err, request=request)
ConnectionError: ('Connection aborted.', gaierror(-2, 'Name or service not known'))
2019-08-07 21:13:21,237 - octoprint.server - INFO - Listening on http://0.0.0.0:5000
2019-08-07 21:13:21,239 - octoprint.plugins.discovery - INFO - Registered OctoPrint instance on hbot for SSDP
2019-08-07 21:13:21,242 - octoprint.plugins.portlister - INFO - Port Lister () {}
2019-08-07 21:13:22,184 - octoprint.plugins.announcements - ERROR - Could not fetch channel _important from http://octoprint.org/feeds/important.xml: [SSL: CERTIFICATE_VERIFY_FAILED] certificate verify failed (_ssl.c:590)
Traceback (most recent call last):
  File "/usr/lib/python2.7/site-packages/octoprint/plugins/announcements/__init__.py", line 269, in _get_channel_data_from_network
    r = requests.get(url)
  File "/usr/lib/python2.7/site-packages/requests/api.py", line 69, in get
    return request('get', url, params=params, **kwargs)
  File "/usr/lib/python2.7/site-packages/requests/api.py", line 50, in request
    response = session.request(method=method, url=url, **kwargs)
  File "/usr/lib/python2.7/site-packages/requests/sessions.py", line 465, in request
    resp = self.send(prep, **send_kwargs)
  File "/usr/lib/python2.7/site-packages/requests/sessions.py", line 594, in send
    history = [resp for resp in gen] if allow_redirects else []
  File "/usr/lib/python2.7/site-packages/requests/sessions.py", line 196, in resolve_redirects
    **adapter_kwargs
  File "/usr/lib/python2.7/site-packages/requests/sessions.py", line 573, in send
    r = adapter.send(request, **kwargs)
  File "/usr/lib/python2.7/site-packages/requests/adapters.py", line 431, in send
    raise SSLError(e, request=request)
SSLError: [SSL: CERTIFICATE_VERIFY_FAILED] certificate verify failed (_ssl.c:590)
2019-08-07 21:13:22,264 - octoprint.server - INFO - Preemptively caching / for {'query_string': 'l10n=en', 'path': '/', 'base_url': 'http://hbot.local:5000/'}
