2016-10-05 21:34:37,758 - octoprint.server.api - INFO - Performing command: sudo halt
2016-10-05 21:34:47,752 - octoprint.server - INFO - Starting OctoPrint 1.2.15 (HEAD -> master branch)
2016-10-05 21:34:47,781 - octoprint.plugin.core - INFO - Loading plugins from /home/rhradec/.octoprint/plugins, /usr/lib/python2.7/site-packages/octoprint/plugins and installed plugin packages...
2016-10-05 21:34:51,079 - octoprint.plugins.discovery - INFO - pybonjour is not installed, Zeroconf Discovery won't be available
2016-10-05 21:34:51,082 - octoprint.plugin.core - INFO - Found 17 plugin(s) providing 16 mixin implementations, 15 hook handlers
2016-10-05 21:34:51,093 - octoprint.filemanager.storage - INFO - Initializing the file metadata for /home/rhradec/.octoprint/uploads...
2016-10-05 21:34:51,220 - octoprint.filemanager.storage - INFO - ... file metadata for /home/rhradec/.octoprint/uploads initialized successfully.
2016-10-05 21:34:55,382 - octoprint.util.pip - INFO - Found pip at /bin/pip2, version is 8.1.2
2016-10-05 21:34:55,731 - octoprint.plugins.softwareupdate - INFO - Loaded version cache from disk
2016-10-05 21:34:55,741 - octoprint.plugin.core - INFO - Initialized 16 plugin implementation(s)
2016-10-05 21:34:55,753 - octoprint.plugin.core - INFO - 17 plugin(s) registered with the system:
|  Active Filters (0.0.1) = /usr/lib/python2.7/site-packages/octoprint_active_filters
|  Announcement Plugin (bundled) = /usr/lib/python2.7/site-packages/octoprint/plugins/announcements
|  BQ Android App Companion (0.1.1) = /usr/lib/python2.7/site-packages/octoprint_bqappcompanion
|  Cost Plugin (0.1.2) = /usr/lib/python2.7/site-packages/octoprint_cost
| !CuraEngine (<= 15.04) (bundled) = /usr/lib/python2.7/site-packages/octoprint/plugins/cura
|  Custom Control Editor (0.2.1) = /usr/lib/python2.7/site-packages/octoprint_customControl
|  Discovery (bundled) = /usr/lib/python2.7/site-packages/octoprint/plugins/discovery
|  EEPROM Marlin Editor Plugin (0.1.0) = /usr/lib/python2.7/site-packages/octoprint_eeprom_marlin
|  Plugin Manager (bundled) = /usr/lib/python2.7/site-packages/octoprint/plugins/pluginmanager
|  PortLister (0.1.5) = /usr/lib/python2.7/site-packages/octoprint_portlister
|  RequestSpinner (0.1.1) = /usr/lib/python2.7/site-packages/octoprint_requestspinner
|  ScreenSquish (0.1) = /usr/lib/python2.7/site-packages/octoprint_ScreenSquish
|  Software Update (bundled) = /usr/lib/python2.7/site-packages/octoprint/plugins/softwareupdate
|  System Command Editor (0.3.1) = /usr/lib/python2.7/site-packages/octoprint_systemcommandeditor
|  TouchUI (0.3.4) = /usr/lib/python2.7/site-packages/octoprint_touchui
|  Virtual Printer (bundled) = /usr/lib/python2.7/site-packages/octoprint/plugins/virtual_printer
|  Yamlpatcher (0.1.1) = /usr/lib/python2.7/site-packages/octoprint_yamlpatcher
2016-10-05 21:34:55,756 - octoprint.filemanager - INFO - Adding backlog items from all storage types to analysis queue...
2016-10-05 21:34:55,769 - octoprint.filemanager - INFO - Added 0 items from storage type "local" to analysis queue
2016-10-05 21:34:55,775 - octoprint.server - INFO - Reset webasset folder /home/rhradec/.octoprint/generated/webassets...
2016-10-05 21:34:55,803 - octoprint.server - INFO - Reset webasset folder /home/rhradec/.octoprint/generated/.webassets-cache...
2016-10-05 21:34:56,964 - octoprint.plugins.pluginmanager - ERROR - Could not fetch plugins from repository at http://plugins.octoprint.org/plugins.json: ('Connection aborted.', gaierror(-2, 'Name or service not known'))
Traceback (most recent call last):
  File "/usr/lib/python2.7/site-packages/octoprint/plugins/pluginmanager/__init__.py", line 542, in _fetch_repository_from_url
    r = requests.get(repository_url)
  File "/usr/lib/python2.7/site-packages/requests/api.py", line 69, in get
    return request('get', url, params=params, **kwargs)
  File "/usr/lib/python2.7/site-packages/requests/api.py", line 50, in request
    response = session.request(method=method, url=url, **kwargs)
  File "/usr/lib/python2.7/site-packages/requests/sessions.py", line 465, in request
    resp = self.send(prep, **send_kwargs)
  File "/usr/lib/python2.7/site-packages/requests/sessions.py", line 573, in send
    r = adapter.send(request, **kwargs)
  File "/usr/lib/python2.7/site-packages/requests/adapters.py", line 415, in send
    raise ConnectionError(err, request=request)
ConnectionError: ('Connection aborted.', gaierror(-2, 'Name or service not known'))
2016-10-05 21:34:56,983 - octoprint.server - INFO - Listening on http://0.0.0.0:5000
2016-10-05 21:34:56,986 - octoprint.plugins.portlister - INFO - Port Lister () {}
2016-10-05 21:34:57,027 - octoprint.plugins.announcements - ERROR - Could not fetch channel _important from http://octoprint.org/feeds/important.xml: ('Connection aborted.', gaierror(-2, 'Name or service not known'))
Traceback (most recent call last):
  File "/usr/lib/python2.7/site-packages/octoprint/plugins/announcements/__init__.py", line 269, in _get_channel_data_from_network
    r = requests.get(url)
  File "/usr/lib/python2.7/site-packages/requests/api.py", line 69, in get
    return request('get', url, params=params, **kwargs)
  File "/usr/lib/python2.7/site-packages/requests/api.py", line 50, in request
    response = session.request(method=method, url=url, **kwargs)
  File "/usr/lib/python2.7/site-packages/requests/sessions.py", line 465, in request
    resp = self.send(prep, **send_kwargs)
  File "/usr/lib/python2.7/site-packages/requests/sessions.py", line 573, in send
    r = adapter.send(request, **kwargs)
  File "/usr/lib/python2.7/site-packages/requests/adapters.py", line 415, in send
    raise ConnectionError(err, request=request)
ConnectionError: ('Connection aborted.', gaierror(-2, 'Name or service not known'))
2016-10-05 21:34:57,102 - octoprint.server - INFO - Preemptively caching / for {'query_string': 'l10n=en', 'path': '/', 'base_url': 'http://hbot.local:5000/'}
2016-10-05 21:38:05,962 - octoprint.plugins.portlister - WARNING - Not auto connecting because printer is not closed nor in error state.
2016-10-05 21:38:05,965 - octoprint.plugins.portlister - WARNING - Not auto connecting because printer is not closed nor in error state.
2016-10-05 21:34:47,580 - octoprint.server - INFO - Starting OctoPrint 1.2.15 (HEAD -> master branch)
2016-10-05 21:34:47,607 - octoprint.plugin.core - INFO - Loading plugins from /home/rhradec/.octoprint/plugins, /usr/lib/python2.7/site-packages/octoprint/plugins and installed plugin packages...
2016-10-05 21:34:50,301 - octoprint.plugins.discovery - INFO - pybonjour is not installed, Zeroconf Discovery won't be available
2016-10-05 21:34:50,303 - octoprint.plugin.core - INFO - Found 17 plugin(s) providing 16 mixin implementations, 15 hook handlers
2016-10-05 21:34:50,315 - octoprint.filemanager.storage - INFO - Initializing the file metadata for /home/rhradec/.octoprint/uploads...
2016-10-05 21:34:50,436 - octoprint.filemanager.storage - INFO - ... file metadata for /home/rhradec/.octoprint/uploads initialized successfully.
2016-10-05 21:34:54,460 - octoprint.util.pip - INFO - Found pip at /bin/pip2, version is 8.1.2
2016-10-05 21:34:54,788 - octoprint.plugins.softwareupdate - INFO - Loaded version cache from disk
2016-10-05 21:34:54,798 - octoprint.plugin.core - INFO - Initialized 16 plugin implementation(s)
2016-10-05 21:34:54,810 - octoprint.plugin.core - INFO - 17 plugin(s) registered with the system:
|  Active Filters (0.0.1) = /usr/lib/python2.7/site-packages/octoprint_active_filters
|  Announcement Plugin (bundled) = /usr/lib/python2.7/site-packages/octoprint/plugins/announcements
|  BQ Android App Companion (0.1.1) = /usr/lib/python2.7/site-packages/octoprint_bqappcompanion
|  Cost Plugin (0.1.2) = /usr/lib/python2.7/site-packages/octoprint_cost
| !CuraEngine (<= 15.04) (bundled) = /usr/lib/python2.7/site-packages/octoprint/plugins/cura
|  Custom Control Editor (0.2.1) = /usr/lib/python2.7/site-packages/octoprint_customControl
|  Discovery (bundled) = /usr/lib/python2.7/site-packages/octoprint/plugins/discovery
|  EEPROM Marlin Editor Plugin (0.1.0) = /usr/lib/python2.7/site-packages/octoprint_eeprom_marlin
|  Plugin Manager (bundled) = /usr/lib/python2.7/site-packages/octoprint/plugins/pluginmanager
|  PortLister (0.1.5) = /usr/lib/python2.7/site-packages/octoprint_portlister
|  RequestSpinner (0.1.1) = /usr/lib/python2.7/site-packages/octoprint_requestspinner
|  ScreenSquish (0.1) = /usr/lib/python2.7/site-packages/octoprint_ScreenSquish
|  Software Update (bundled) = /usr/lib/python2.7/site-packages/octoprint/plugins/softwareupdate
|  System Command Editor (0.3.1) = /usr/lib/python2.7/site-packages/octoprint_systemcommandeditor
|  TouchUI (0.3.4) = /usr/lib/python2.7/site-packages/octoprint_touchui
|  Virtual Printer (bundled) = /usr/lib/python2.7/site-packages/octoprint/plugins/virtual_printer
|  Yamlpatcher (0.1.1) = /usr/lib/python2.7/site-packages/octoprint_yamlpatcher
2016-10-05 21:34:54,813 - octoprint.filemanager - INFO - Adding backlog items from all storage types to analysis queue...
2016-10-05 21:34:54,827 - octoprint.filemanager - INFO - Added 0 items from storage type "local" to analysis queue
2016-10-05 21:34:54,831 - octoprint.server - INFO - Reset webasset folder /home/rhradec/.octoprint/generated/webassets...
2016-10-05 21:34:54,850 - octoprint.server - INFO - Reset webasset folder /home/rhradec/.octoprint/generated/.webassets-cache...
2016-10-05 21:34:55,762 - octoprint.plugins.discovery - INFO - Registered OctoPrint instance on hbot for SSDP
2016-10-05 21:34:55,798 - octoprint.plugins.pluginmanager - ERROR - Could not fetch plugins from repository at http://plugins.octoprint.org/plugins.json: ('Connection aborted.', gaierror(-2, 'Name or service not known'))
Traceback (most recent call last):
  File "/usr/lib/python2.7/site-packages/octoprint/plugins/pluginmanager/__init__.py", line 542, in _fetch_repository_from_url
    r = requests.get(repository_url)
  File "/usr/lib/python2.7/site-packages/requests/api.py", line 69, in get
    return request('get', url, params=params, **kwargs)
  File "/usr/lib/python2.7/site-packages/requests/api.py", line 50, in request
    response = session.request(method=method, url=url, **kwargs)
  File "/usr/lib/python2.7/site-packages/requests/sessions.py", line 465, in request
    resp = self.send(prep, **send_kwargs)
  File "/usr/lib/python2.7/site-packages/requests/sessions.py", line 573, in send
    r = adapter.send(request, **kwargs)
  File "/usr/lib/python2.7/site-packages/requests/adapters.py", line 415, in send
    raise ConnectionError(err, request=request)
ConnectionError: ('Connection aborted.', gaierror(-2, 'Name or service not known'))
2016-10-05 21:34:55,815 - octoprint.server - INFO - Listening on http://0.0.0.0:5000
2016-10-05 21:34:55,817 - octoprint.plugins.portlister - INFO - Port Lister () {}
2016-10-05 21:34:56,076 - octoprint.plugins.announcements - INFO - Loaded channel _important from http://octoprint.org/feeds/important.xml in 0.24s
2016-10-05 21:34:57,065 - octoprint.server - INFO - Preemptively caching / for {'query_string': 'l10n=en', 'path': '/', 'base_url': 'http://hbot.local:5000/'}
2016-10-06 11:52:02,140 - octoprint.server.util.sockjs - INFO - New connection from client: 192.168.10.10
2016-10-06 11:52:03,901 - octoprint.plugins.softwareupdate - ERROR - Could not check active_filters for updates
Traceback (most recent call last):
  File "/usr/lib/python2.7/site-packages/octoprint/plugins/softwareupdate/__init__.py", line 482, in _get_current_version
    information, is_current = version_checker.get_latest(target, check)
  File "/usr/lib/python2.7/site-packages/octoprint/plugins/softwareupdate/version_checks/github_release.py", line 134, in get_latest
    include_prerelease=include_prerelease)
  File "/usr/lib/python2.7/site-packages/octoprint/plugins/softwareupdate/version_checks/github_release.py", line 19, in _get_latest_release
    r = requests.get(RELEASE_URL.format(user=user, repo=repo))
  File "/usr/lib/python2.7/site-packages/requests/api.py", line 69, in get
    return request('get', url, params=params, **kwargs)
  File "/usr/lib/python2.7/site-packages/requests/api.py", line 50, in request
    response = session.request(method=method, url=url, **kwargs)
  File "/usr/lib/python2.7/site-packages/requests/sessions.py", line 465, in request
    resp = self.send(prep, **send_kwargs)
  File "/usr/lib/python2.7/site-packages/requests/sessions.py", line 573, in send
    r = adapter.send(request, **kwargs)
  File "/usr/lib/python2.7/site-packages/requests/adapters.py", line 415, in send
    raise ConnectionError(err, request=request)
ConnectionError: ('Connection aborted.', gaierror(-2, 'Name or service not known'))
2016-10-06 11:52:03,926 - octoprint.plugins.softwareupdate - ERROR - Could not check touchui for updates
Traceback (most recent call last):
  File "/usr/lib/python2.7/site-packages/octoprint/plugins/softwareupdate/__init__.py", line 482, in _get_current_version
    information, is_current = version_checker.get_latest(target, check)
  File "/usr/lib/python2.7/site-packages/octoprint/plugins/softwareupdate/version_checks/github_release.py", line 134, in get_latest
    include_prerelease=include_prerelease)
  File "/usr/lib/python2.7/site-packages/octoprint/plugins/softwareupdate/version_checks/github_release.py", line 19, in _get_latest_release
    r = requests.get(RELEASE_URL.format(user=user, repo=repo))
  File "/usr/lib/python2.7/site-packages/requests/api.py", line 69, in get
    return request('get', url, params=params, **kwargs)
  File "/usr/lib/python2.7/site-packages/requests/api.py", line 50, in request
    response = session.request(method=method, url=url, **kwargs)
  File "/usr/lib/python2.7/site-packages/requests/sessions.py", line 465, in request
    resp = self.send(prep, **send_kwargs)
  File "/usr/lib/python2.7/site-packages/requests/sessions.py", line 573, in send
    r = adapter.send(request, **kwargs)
  File "/usr/lib/python2.7/site-packages/requests/adapters.py", line 415, in send
    raise ConnectionError(err, request=request)
ConnectionError: ('Connection aborted.', gaierror(-2, 'Name or service not known'))
2016-10-06 11:52:03,944 - octoprint.plugins.softwareupdate - ERROR - Could not check customcontrol for updates
Traceback (most recent call last):
  File "/usr/lib/python2.7/site-packages/octoprint/plugins/softwareupdate/__init__.py", line 482, in _get_current_version
    information, is_current = version_checker.get_latest(target, check)
  File "/usr/lib/python2.7/site-packages/octoprint/plugins/softwareupdate/version_checks/github_release.py", line 134, in get_latest
    include_prerelease=include_prerelease)
  File "/usr/lib/python2.7/site-packages/octoprint/plugins/softwareupdate/version_checks/github_release.py", line 19, in _get_latest_release
    r = requests.get(RELEASE_URL.format(user=user, repo=repo))
  File "/usr/lib/python2.7/site-packages/requests/api.py", line 69, in get
    return request('get', url, params=params, **kwargs)
  File "/usr/lib/python2.7/site-packages/requests/api.py", line 50, in request
    response = session.request(method=method, url=url, **kwargs)
  File "/usr/lib/python2.7/site-packages/requests/sessions.py", line 465, in request
    resp = self.send(prep, **send_kwargs)
  File "/usr/lib/python2.7/site-packages/requests/sessions.py", line 573, in send
    r = adapter.send(request, **kwargs)
  File "/usr/lib/python2.7/site-packages/requests/adapters.py", line 415, in send
    raise ConnectionError(err, request=request)
ConnectionError: ('Connection aborted.', gaierror(-2, 'Name or service not known'))
2016-10-06 11:52:03,963 - octoprint.plugins.softwareupdate - ERROR - Could not check portlister for updates
Traceback (most recent call last):
  File "/usr/lib/python2.7/site-packages/octoprint/plugins/softwareupdate/__init__.py", line 482, in _get_current_version
    information, is_current = version_checker.get_latest(target, check)
  File "/usr/lib/python2.7/site-packages/octoprint/plugins/softwareupdate/version_checks/github_release.py", line 134, in get_latest
    include_prerelease=include_prerelease)
  File "/usr/lib/python2.7/site-packages/octoprint/plugins/softwareupdate/version_checks/github_release.py", line 19, in _get_latest_release
    r = requests.get(RELEASE_URL.format(user=user, repo=repo))
  File "/usr/lib/python2.7/site-packages/requests/api.py", line 69, in get
    return request('get', url, params=params, **kwargs)
  File "/usr/lib/python2.7/site-packages/requests/api.py", line 50, in request
    response = session.request(method=method, url=url, **kwargs)
  File "/usr/lib/python2.7/site-packages/requests/sessions.py", line 465, in request
    resp = self.send(prep, **send_kwargs)
  File "/usr/lib/python2.7/site-packages/requests/sessions.py", line 573, in send
    r = adapter.send(request, **kwargs)
  File "/usr/lib/python2.7/site-packages/requests/adapters.py", line 415, in send
    raise ConnectionError(err, request=request)
ConnectionError: ('Connection aborted.', gaierror(-2, 'Name or service not known'))
2016-10-06 11:52:04,076 - octoprint.plugins.softwareupdate - ERROR - Could not check requestspinner for updates
Traceback (most recent call last):
  File "/usr/lib/python2.7/site-packages/octoprint/plugins/softwareupdate/__init__.py", line 482, in _get_current_version
    information, is_current = version_checker.get_latest(target, check)
  File "/usr/lib/python2.7/site-packages/octoprint/plugins/softwareupdate/version_checks/github_release.py", line 134, in get_latest
    include_prerelease=include_prerelease)
  File "/usr/lib/python2.7/site-packages/octoprint/plugins/softwareupdate/version_checks/github_release.py", line 19, in _get_latest_release
    r = requests.get(RELEASE_URL.format(user=user, repo=repo))
  File "/usr/lib/python2.7/site-packages/requests/api.py", line 69, in get
    return request('get', url, params=params, **kwargs)
  File "/usr/lib/python2.7/site-packages/requests/api.py", line 50, in request
    response = session.request(method=method, url=url, **kwargs)
  File "/usr/lib/python2.7/site-packages/requests/sessions.py", line 465, in request
    resp = self.send(prep, **send_kwargs)
  File "/usr/lib/python2.7/site-packages/requests/sessions.py", line 573, in send
    r = adapter.send(request, **kwargs)
  File "/usr/lib/python2.7/site-packages/requests/adapters.py", line 415, in send
    raise ConnectionError(err, request=request)
ConnectionError: ('Connection aborted.', gaierror(-2, 'Name or service not known'))
2016-10-06 11:52:04,089 - octoprint.plugins.softwareupdate - ERROR - Could not check cost for updates
Traceback (most recent call last):
  File "/usr/lib/python2.7/site-packages/octoprint/plugins/softwareupdate/__init__.py", line 482, in _get_current_version
    information, is_current = version_checker.get_latest(target, check)
  File "/usr/lib/python2.7/site-packages/octoprint/plugins/softwareupdate/version_checks/github_release.py", line 134, in get_latest
    include_prerelease=include_prerelease)
  File "/usr/lib/python2.7/site-packages/octoprint/plugins/softwareupdate/version_checks/github_release.py", line 19, in _get_latest_release
    r = requests.get(RELEASE_URL.format(user=user, repo=repo))
  File "/usr/lib/python2.7/site-packages/requests/api.py", line 69, in get
    return request('get', url, params=params, **kwargs)
  File "/usr/lib/python2.7/site-packages/requests/api.py", line 50, in request
    response = session.request(method=method, url=url, **kwargs)
  File "/usr/lib/python2.7/site-packages/requests/sessions.py", line 465, in request
    resp = self.send(prep, **send_kwargs)
  File "/usr/lib/python2.7/site-packages/requests/sessions.py", line 573, in send
    r = adapter.send(request, **kwargs)
  File "/usr/lib/python2.7/site-packages/requests/adapters.py", line 415, in send
    raise ConnectionError(err, request=request)
ConnectionError: ('Connection aborted.', gaierror(-2, 'Name or service not known'))
2016-10-06 11:52:04,103 - octoprint.plugins.softwareupdate - ERROR - Could not check systemcommandeditor for updates
Traceback (most recent call last):
  File "/usr/lib/python2.7/site-packages/octoprint/plugins/softwareupdate/__init__.py", line 482, in _get_current_version
    information, is_current = version_checker.get_latest(target, check)
  File "/usr/lib/python2.7/site-packages/octoprint/plugins/softwareupdate/version_checks/github_release.py", line 134, in get_latest
    include_prerelease=include_prerelease)
  File "/usr/lib/python2.7/site-packages/octoprint/plugins/softwareupdate/version_checks/github_release.py", line 19, in _get_latest_release
    r = requests.get(RELEASE_URL.format(user=user, repo=repo))
  File "/usr/lib/python2.7/site-packages/requests/api.py", line 69, in get
    return request('get', url, params=params, **kwargs)
  File "/usr/lib/python2.7/site-packages/requests/api.py", line 50, in request
    response = session.request(method=method, url=url, **kwargs)
  File "/usr/lib/python2.7/site-packages/requests/sessions.py", line 465, in request
    resp = self.send(prep, **send_kwargs)
  File "/usr/lib/python2.7/site-packages/requests/sessions.py", line 573, in send
    r = adapter.send(request, **kwargs)
  File "/usr/lib/python2.7/site-packages/requests/adapters.py", line 415, in send
    raise ConnectionError(err, request=request)
ConnectionError: ('Connection aborted.', gaierror(-2, 'Name or service not known'))
2016-10-06 11:52:04,117 - octoprint.plugins.softwareupdate - ERROR - Could not check bqappcompanion for updates
Traceback (most recent call last):
  File "/usr/lib/python2.7/site-packages/octoprint/plugins/softwareupdate/__init__.py", line 482, in _get_current_version
    information, is_current = version_checker.get_latest(target, check)
  File "/usr/lib/python2.7/site-packages/octoprint/plugins/softwareupdate/version_checks/github_release.py", line 134, in get_latest
    include_prerelease=include_prerelease)
  File "/usr/lib/python2.7/site-packages/octoprint/plugins/softwareupdate/version_checks/github_release.py", line 19, in _get_latest_release
    r = requests.get(RELEASE_URL.format(user=user, repo=repo))
  File "/usr/lib/python2.7/site-packages/requests/api.py", line 69, in get
    return request('get', url, params=params, **kwargs)
  File "/usr/lib/python2.7/site-packages/requests/api.py", line 50, in request
    response = session.request(method=method, url=url, **kwargs)
  File "/usr/lib/python2.7/site-packages/requests/sessions.py", line 465, in request
    resp = self.send(prep, **send_kwargs)
  File "/usr/lib/python2.7/site-packages/requests/sessions.py", line 573, in send
    r = adapter.send(request, **kwargs)
  File "/usr/lib/python2.7/site-packages/requests/adapters.py", line 415, in send
    raise ConnectionError(err, request=request)
ConnectionError: ('Connection aborted.', gaierror(-2, 'Name or service not known'))
2016-10-06 11:52:04,130 - octoprint.plugins.softwareupdate - ERROR - Could not check yamlpatcher for updates
Traceback (most recent call last):
  File "/usr/lib/python2.7/site-packages/octoprint/plugins/softwareupdate/__init__.py", line 482, in _get_current_version
    information, is_current = version_checker.get_latest(target, check)
  File "/usr/lib/python2.7/site-packages/octoprint/plugins/softwareupdate/version_checks/github_release.py", line 134, in get_latest
    include_prerelease=include_prerelease)
  File "/usr/lib/python2.7/site-packages/octoprint/plugins/softwareupdate/version_checks/github_release.py", line 19, in _get_latest_release
    r = requests.get(RELEASE_URL.format(user=user, repo=repo))
  File "/usr/lib/python2.7/site-packages/requests/api.py", line 69, in get
    return request('get', url, params=params, **kwargs)
  File "/usr/lib/python2.7/site-packages/requests/api.py", line 50, in request
    response = session.request(method=method, url=url, **kwargs)
  File "/usr/lib/python2.7/site-packages/requests/sessions.py", line 465, in request
    resp = self.send(prep, **send_kwargs)
  File "/usr/lib/python2.7/site-packages/requests/sessions.py", line 573, in send
    r = adapter.send(request, **kwargs)
  File "/usr/lib/python2.7/site-packages/requests/adapters.py", line 415, in send
    raise ConnectionError(err, request=request)
ConnectionError: ('Connection aborted.', gaierror(-2, 'Name or service not known'))
2016-10-06 11:52:04,232 - octoprint.plugins.softwareupdate - INFO - Saved version cache to disk
2016-10-06 11:52:04,325 - octoprint.plugins.announcements - ERROR - Could not fetch channel _important from http://octoprint.org/feeds/important.xml: ('Connection aborted.', gaierror(-2, 'Name or service not known'))
Traceback (most recent call last):
  File "/usr/lib/python2.7/site-packages/octoprint/plugins/announcements/__init__.py", line 269, in _get_channel_data_from_network
    r = requests.get(url)
  File "/usr/lib/python2.7/site-packages/requests/api.py", line 69, in get
    return request('get', url, params=params, **kwargs)
  File "/usr/lib/python2.7/site-packages/requests/api.py", line 50, in request
    response = session.request(method=method, url=url, **kwargs)
  File "/usr/lib/python2.7/site-packages/requests/sessions.py", line 465, in request
    resp = self.send(prep, **send_kwargs)
  File "/usr/lib/python2.7/site-packages/requests/sessions.py", line 573, in send
    r = adapter.send(request, **kwargs)
  File "/usr/lib/python2.7/site-packages/requests/adapters.py", line 415, in send
    raise ConnectionError(err, request=request)
ConnectionError: ('Connection aborted.', gaierror(-2, 'Name or service not known'))
2016-10-06 12:27:29,679 - octoprint.plugins.portlister - WARNING - Not auto connecting because printer is not closed nor in error state.
2016-10-06 12:27:29,682 - octoprint.plugins.portlister - WARNING - Not auto connecting because printer is not closed nor in error state.
2016-10-06 12:43:08,599 - octoprint.filemanager.analysis - INFO - Starting analysis of local:ramps_fan_80mm.gcode
2016-10-06 12:59:14,596 - octoprint.filemanager.analysis - INFO - Starting analysis of local:ramps_fan_80mm.gcode
2016-10-06 13:02:55,210 - octoprint.filemanager.analysis - INFO - Starting analysis of local:ramps_fan_80mm.gcode
2016-10-06 13:05:16,178 - octoprint.filemanager.analysis - INFO - Starting analysis of local:ramps_fan_80mm.gcode
2016-10-06 13:08:07,659 - octoprint.filemanager.analysis - INFO - Starting analysis of local:ramps_fan_80mm.gcode
2016-10-06 13:12:54,090 - octoprint.filemanager.analysis - INFO - Starting analysis of local:ramps_fan_80mm.gcode
2016-10-06 13:17:57,325 - octoprint.server.util.sockjs - INFO - Client connection closed: 192.168.10.10
2016-10-06 13:17:59,472 - octoprint.server.util.sockjs - INFO - New connection from client: 192.168.10.10
2016-10-06 13:18:02,283 - octoprint.plugins.announcements - ERROR - Could not fetch channel _important from http://octoprint.org/feeds/important.xml: ('Connection aborted.', gaierror(-2, 'Name or service not known'))
Traceback (most recent call last):
  File "/usr/lib/python2.7/site-packages/octoprint/plugins/announcements/__init__.py", line 269, in _get_channel_data_from_network
    r = requests.get(url)
  File "/usr/lib/python2.7/site-packages/requests/api.py", line 69, in get
    return request('get', url, params=params, **kwargs)
  File "/usr/lib/python2.7/site-packages/requests/api.py", line 50, in request
    response = session.request(method=method, url=url, **kwargs)
  File "/usr/lib/python2.7/site-packages/requests/sessions.py", line 465, in request
    resp = self.send(prep, **send_kwargs)
  File "/usr/lib/python2.7/site-packages/requests/sessions.py", line 573, in send
    r = adapter.send(request, **kwargs)
  File "/usr/lib/python2.7/site-packages/requests/adapters.py", line 415, in send
    raise ConnectionError(err, request=request)
ConnectionError: ('Connection aborted.', gaierror(-2, 'Name or service not known'))
2016-10-06 13:30:58,733 - octoprint.filemanager.analysis - INFO - Starting analysis of local:ramps_fan_80mm.gcode
2016-10-06 13:31:46,062 - octoprint.filemanager.analysis - INFO - Starting analysis of local:ramps_fan_80mm.gcode
2016-10-06 13:31:53,351 - octoprint.filemanager.analysis - INFO - Starting analysis of local:ramps_fan_80mm.gcode
2016-10-06 13:32:00,758 - octoprint.filemanager.analysis - INFO - Starting analysis of local:ramps_fan_80mm.gcode
2016-10-06 16:45:11,805 - octoprint.filemanager.analysis - INFO - Starting analysis of local:ramps_fan_80mm.gcode
2016-10-06 19:02:26,100 - octoprint.filemanager.analysis - INFO - Starting analysis of local:ramps_fan_80mm.gcode
2016-10-06 19:11:19,129 - octoprint.filemanager.analysis - INFO - Starting analysis of local:ramps_fan_80mm.gcode
2016-10-06 19:33:02,649 - octoprint.filemanager.analysis - INFO - Starting analysis of local:ramps_fan_80mm.gcode
2016-10-06 19:53:53,822 - octoprint.filemanager.analysis - INFO - Starting analysis of local:rampspi.0001.STL_Model.gcode
