2017-08-15 21:14:14,699 - octoprint.plugins.announcements - INFO - Loaded channel _important from http://octoprint.org/feeds/important.xml in 8.6e+04s
2017-08-15 21:14:16,036 - octoprint.server - INFO - Preemptively caching / for {'query_string': 'l10n=en', 'path': '/', 'base_url': 'http://hbot.local:5000/'}
2017-08-15 21:14:36,927 - octoprint.plugins.portlister - WARNING - Not auto connecting because printer is not closed nor in error state.
2017-08-15 21:14:36,936 - octoprint.plugins.portlister - WARNING - Not auto connecting because printer is not closed nor in error state.
2017-08-15 21:20:29,676 - tornado.application - ERROR - Uncaught exception GET /static/webassets/packed_libs.js?35d69079 (192.168.10.10)
HTTPServerRequest(protocol='http', host='hbot.local:5000', method='GET', uri='/static/webassets/packed_libs.js?35d69079', version='HTTP/1.1', remote_ip='192.168.10.10', headers={'Accept-Language': 'en-US,en;q=0.8,pt-BR;q=0.6,pt;q=0.4', 'Accept-Encoding': 'gzip, deflate', 'Host': 'hbot.local:5000', 'Accept': '*/*', 'User-Agent': 'Mozilla/5.0 (X11; Linux x86_64) AppleWebKit/537.36 (KHTML, like Gecko) Chrome/59.0.3071.115 Safari/537.36', 'Dnt': '1', 'Connection': 'keep-alive', 'Referer': 'http://hbot.local:5000/', 'Cookie': 'session=.eJyrVopPK0otzlCyKikqTdVRis9MUbKqVlJIUrJS8g_xNYrM9cr2Cw_L9q0KNPXN8sqKzMrIjsr1y_UNya6Ico809XX3rYoKD7VVqtVRykxJzSvJLKnUSywtyYgvqSxIVbLKK83JQZJBMj05N6MyMjwoJ7LcFqy7tDi1KB6nfC0Ay_Y4og.DHVYiA.K_KOFSMXVP1Zu2QRvPAoa61JLhA'})
Traceback (most recent call last):
  File "/usr/lib/python2.7/site-packages/tornado/web.py", line 1334, in _execute
    result = yield result
  File "/usr/lib/python2.7/site-packages/tornado/gen.py", line 628, in run
    value = future.result()
  File "/usr/lib/python2.7/site-packages/tornado/concurrent.py", line 109, in result
    raise_exc_info(self._exc_info)
  File "/usr/lib/python2.7/site-packages/tornado/gen.py", line 631, in run
    yielded = self.gen.throw(*sys.exc_info())
  File "/usr/lib/python2.7/site-packages/tornado/web.py", line 2172, in get
    yield self.flush()
  File "/usr/lib/python2.7/site-packages/tornado/gen.py", line 628, in run
    value = future.result()
  File "/usr/lib/python2.7/site-packages/tornado/concurrent.py", line 111, in result
    raise self._exception
StreamClosedError
2017-08-15 21:20:29,696 - tornado.general - ERROR - Cannot send error response after headers written
2017-08-15 21:20:34,541 - tornado.application - ERROR - Uncaught exception GET /static/webassets/packed_app.js?c2ce04ab (192.168.10.10)
HTTPServerRequest(protocol='http', host='hbot.local:5000', method='GET', uri='/static/webassets/packed_app.js?c2ce04ab', version='HTTP/1.1', remote_ip='192.168.10.10', headers={'Accept-Language': 'en-US,en;q=0.8,pt-BR;q=0.6,pt;q=0.4', 'Accept-Encoding': 'gzip, deflate', 'Host': 'hbot.local:5000', 'Accept': '*/*', 'User-Agent': 'Mozilla/5.0 (X11; Linux x86_64) AppleWebKit/537.36 (KHTML, like Gecko) Chrome/59.0.3071.115 Safari/537.36', 'Dnt': '1', 'Connection': 'keep-alive', 'Referer': 'http://hbot.local:5000/', 'Cookie': 'session=.eJyrVopPK0otzlCyKikqTdVRis9MUbKqVlJIUrJS8g_xNYrM9cr2Cw_L9q0KNPXN8sqKzMrIjsr1y_UNya6Ico809XX3rYoKD7VVqtVRykxJzSvJLKnUSywtyYgvqSxIVbLKK83JQZJBMj05N6MyMjwoJ7LcFqy7tDi1KB6nfC0Ay_Y4og.DHVYiA.K_KOFSMXVP1Zu2QRvPAoa61JLhA'})
Traceback (most recent call last):
  File "/usr/lib/python2.7/site-packages/tornado/web.py", line 1334, in _execute
    result = yield result
  File "/usr/lib/python2.7/site-packages/tornado/gen.py", line 628, in run
    value = future.result()
  File "/usr/lib/python2.7/site-packages/tornado/concurrent.py", line 109, in result
    raise_exc_info(self._exc_info)
  File "/usr/lib/python2.7/site-packages/tornado/gen.py", line 631, in run
    yielded = self.gen.throw(*sys.exc_info())
  File "/usr/lib/python2.7/site-packages/tornado/web.py", line 2172, in get
    yield self.flush()
  File "/usr/lib/python2.7/site-packages/tornado/gen.py", line 628, in run
    value = future.result()
  File "/usr/lib/python2.7/site-packages/tornado/concurrent.py", line 111, in result
    raise self._exception
StreamClosedError
2017-08-15 21:20:34,544 - tornado.general - ERROR - Cannot send error response after headers written
2017-08-15 21:22:01,542 - tornado.application - ERROR - Uncaught exception GET /static/webassets/packed_app.js?c2ce04ab (192.168.10.10)
HTTPServerRequest(protocol='http', host='hbot.local:5000', method='GET', uri='/static/webassets/packed_app.js?c2ce04ab', version='HTTP/1.1', remote_ip='192.168.10.10', headers={'Accept-Language': 'en-US,en;q=0.8,pt-BR;q=0.6,pt;q=0.4', 'Accept-Encoding': 'gzip, deflate', 'Dnt': '1', 'Host': 'hbot.local:5000', 'Accept': '*/*', 'User-Agent': 'Mozilla/5.0 (X11; Linux x86_64) AppleWebKit/537.36 (KHTML, like Gecko) Chrome/59.0.3071.115 Safari/537.36', 'If-Range': '1502856876', 'Connection': 'keep-alive', 'Referer': 'http://hbot.local:5000/', 'Range': 'bytes=166287-834516', 'Cookie': 'session=.eJyrVopPK0otzlCyKikqTdVRis9MUbKqVlJIUrJS8g_xNYrM9cr2Cw_L9q0KNPXN8sqKzMrIjsr1y_UNya6Ico809XX3rYoKD7VVqtVRykxJzSvJLKnUSywtyYgvqSxIVbLKK83JQZJBMj05N6MyMjwoJ7LcFqy7tDi1KB6nfC0Ay_Y4og.DHVZjw.PA3epG47smyhQRuUmP2NxwBB0p4'})
Traceback (most recent call last):
  File "/usr/lib/python2.7/site-packages/tornado/web.py", line 1334, in _execute
    result = yield result
  File "/usr/lib/python2.7/site-packages/tornado/gen.py", line 628, in run
    value = future.result()
  File "/usr/lib/python2.7/site-packages/tornado/concurrent.py", line 109, in result
    raise_exc_info(self._exc_info)
  File "/usr/lib/python2.7/site-packages/tornado/gen.py", line 631, in run
    yielded = self.gen.throw(*sys.exc_info())
  File "/usr/lib/python2.7/site-packages/tornado/web.py", line 2172, in get
    yield self.flush()
  File "/usr/lib/python2.7/site-packages/tornado/gen.py", line 628, in run
    value = future.result()
  File "/usr/lib/python2.7/site-packages/tornado/concurrent.py", line 111, in result
    raise self._exception
StreamClosedError
2017-08-15 21:22:01,546 - tornado.general - ERROR - Cannot send error response after headers written
2017-08-15 21:22:19,035 - tornado.application - ERROR - Uncaught exception GET /static/webassets/packed_libs.js?35d69079 (192.168.10.10)
HTTPServerRequest(protocol='http', host='hbot.local:5000', method='GET', uri='/static/webassets/packed_libs.js?35d69079', version='HTTP/1.1', remote_ip='192.168.10.10', headers={'Accept-Language': 'en-US,en;q=0.8,pt-BR;q=0.6,pt;q=0.4', 'Accept-Encoding': 'gzip, deflate', 'Dnt': '1', 'Host': 'hbot.local:5000', 'Accept': '*/*', 'User-Agent': 'Mozilla/5.0 (X11; Linux x86_64) AppleWebKit/537.36 (KHTML, like Gecko) Chrome/59.0.3071.115 Safari/537.36', 'If-Range': '1502856873', 'Connection': 'keep-alive', 'Referer': 'http://hbot.local:5000/', 'Range': 'bytes=494694-791584', 'Cookie': 'session=.eJyrVopPK0otzlCyKikqTdVRis9MUbKqVlJIUrJS8g_xNYrM9cr2Cw_L9q0KNPXN8sqKzMrIjsr1y_UNya6Ico809XX3rYoKD7VVqtVRykxJzSvJLKnUSywtyYgvqSxIVbLKK83JQZJBMj05N6MyMjwoJ7LcFqy7tDi1KB6nfC0Ay_Y4og.DHVZ6A.vuS9wt_zqN3Lok9pJTrEX82XWHo'})
Traceback (most recent call last):
  File "/usr/lib/python2.7/site-packages/tornado/web.py", line 1334, in _execute
    result = yield result
  File "/usr/lib/python2.7/site-packages/tornado/gen.py", line 628, in run
    value = future.result()
  File "/usr/lib/python2.7/site-packages/tornado/concurrent.py", line 109, in result
    raise_exc_info(self._exc_info)
  File "/usr/lib/python2.7/site-packages/tornado/gen.py", line 631, in run
    yielded = self.gen.throw(*sys.exc_info())
  File "/usr/lib/python2.7/site-packages/tornado/web.py", line 2172, in get
    yield self.flush()
  File "/usr/lib/python2.7/site-packages/tornado/gen.py", line 628, in run
    value = future.result()
  File "/usr/lib/python2.7/site-packages/tornado/concurrent.py", line 111, in result
    raise self._exception
StreamClosedError
2017-08-15 21:22:19,038 - tornado.general - ERROR - Cannot send error response after headers written
2017-08-15 21:22:38,076 - tornado.application - ERROR - Uncaught exception GET /static/webassets/packed_libs.js?35d69079 (192.168.10.10)
HTTPServerRequest(protocol='http', host='hbot.local:5000', method='GET', uri='/static/webassets/packed_libs.js?35d69079', version='HTTP/1.1', remote_ip='192.168.10.10', headers={'Accept-Language': 'en-US,en;q=0.8,pt-BR;q=0.6,pt;q=0.4', 'Accept-Encoding': 'gzip, deflate', 'Dnt': '1', 'Host': 'hbot.local:5000', 'Accept': '*/*', 'User-Agent': 'Mozilla/5.0 (X11; Linux x86_64) AppleWebKit/537.36 (KHTML, like Gecko) Chrome/59.0.3071.115 Safari/537.36', 'If-Range': '1502856873', 'Connection': 'keep-alive', 'Referer': 'http://hbot.local:5000/', 'Range': 'bytes=494694-791584', 'Cookie': 'session=.eJyrVopPK0otzlCyKikqTdVRis9MUbKqVlJIUrJS8g_xNYrM9cr2Cw_L9q0KNPXN8sqKzMrIjsr1y_UNya6Ico809XX3rYoKD7VVqtVRykxJzSvJLKnUSywtyYgvqSxIVbLKK83JQZJBMj05N6MyMjwoJ7LcFqy7tDi1KB6nfC0Ay_Y4og.DHVZ7A.-qEvSBMcKEW3iC1qwOvkNwjok_w'})
Traceback (most recent call last):
  File "/usr/lib/python2.7/site-packages/tornado/web.py", line 1334, in _execute
    result = yield result
  File "/usr/lib/python2.7/site-packages/tornado/gen.py", line 628, in run
    value = future.result()
  File "/usr/lib/python2.7/site-packages/tornado/concurrent.py", line 109, in result
    raise_exc_info(self._exc_info)
  File "/usr/lib/python2.7/site-packages/tornado/gen.py", line 631, in run
    yielded = self.gen.throw(*sys.exc_info())
  File "/usr/lib/python2.7/site-packages/tornado/web.py", line 2172, in get
    yield self.flush()
  File "/usr/lib/python2.7/site-packages/tornado/gen.py", line 628, in run
    value = future.result()
  File "/usr/lib/python2.7/site-packages/tornado/concurrent.py", line 111, in result
    raise self._exception
StreamClosedError
2017-08-15 21:22:38,079 - tornado.general - ERROR - Cannot send error response after headers written
2017-08-15 21:22:38,821 - tornado.application - ERROR - Uncaught exception GET /static/webassets/packed_app.js?c2ce04ab (192.168.10.10)
HTTPServerRequest(protocol='http', host='hbot.local:5000', method='GET', uri='/static/webassets/packed_app.js?c2ce04ab', version='HTTP/1.1', remote_ip='192.168.10.10', headers={'Accept-Language': 'en-US,en;q=0.8,pt-BR;q=0.6,pt;q=0.4', 'Accept-Encoding': 'gzip, deflate', 'Host': 'hbot.local:5000', 'Accept': '*/*', 'User-Agent': 'Mozilla/5.0 (X11; Linux x86_64) AppleWebKit/537.36 (KHTML, like Gecko) Chrome/59.0.3071.115 Safari/537.36', 'Dnt': '1', 'Connection': 'keep-alive', 'Referer': 'http://hbot.local:5000/', 'Cookie': 'session=.eJyrVopPK0otzlCyKikqTdVRis9MUbKqVlJIUrJS8g_xNYrM9cr2Cw_L9q0KNPXN8sqKzMrIjsr1y_UNya6Ico809XX3rYoKD7VVqtVRykxJzSvJLKnUSywtyYgvqSxIVbLKK83JQZJBMj05N6MyMjwoJ7LcFqy7tDi1KB6nfC0Ay_Y4og.DHVZ7A.-qEvSBMcKEW3iC1qwOvkNwjok_w'})
Traceback (most recent call last):
  File "/usr/lib/python2.7/site-packages/tornado/web.py", line 1334, in _execute
    result = yield result
  File "/usr/lib/python2.7/site-packages/tornado/gen.py", line 628, in run
    value = future.result()
  File "/usr/lib/python2.7/site-packages/tornado/concurrent.py", line 109, in result
    raise_exc_info(self._exc_info)
  File "/usr/lib/python2.7/site-packages/tornado/gen.py", line 631, in run
    yielded = self.gen.throw(*sys.exc_info())
  File "/usr/lib/python2.7/site-packages/tornado/web.py", line 2172, in get
    yield self.flush()
  File "/usr/lib/python2.7/site-packages/tornado/gen.py", line 628, in run
    value = future.result()
  File "/usr/lib/python2.7/site-packages/tornado/concurrent.py", line 111, in result
    raise self._exception
StreamClosedError
2017-08-15 21:22:38,825 - tornado.general - ERROR - Cannot send error response after headers written
2017-08-15 21:26:58,141 - tornado.application - ERROR - Uncaught exception GET /static/webassets/packed_libs.js?35d69079 (192.168.10.10)
HTTPServerRequest(protocol='http', host='hbot.local:5000', method='GET', uri='/static/webassets/packed_libs.js?35d69079', version='HTTP/1.1', remote_ip='192.168.10.10', headers={'Accept-Language': 'en-US,en;q=0.8,pt-BR;q=0.6,pt;q=0.4', 'Accept-Encoding': 'gzip, deflate', 'Dnt': '1', 'Host': 'hbot.local:5000', 'Accept': '*/*', 'User-Agent': 'Mozilla/5.0 (X11; Linux x86_64) AppleWebKit/537.36 (KHTML, like Gecko) Chrome/59.0.3071.115 Safari/537.36', 'If-Range': '1502856873', 'Connection': 'keep-alive', 'Referer': 'http://hbot.local:5000/', 'Range': 'bytes=480503-791584', 'Cookie': 'session=.eJyrVopPK0otzlCyKikqTdVRis9MUbKqVlJIUrJS8g_xNYrM9cr2Cw_L9q0KNPXN8sqKzMrIjsr1y_UNya6Ico809XX3rYoKD7VVqtVRykxJzSvJLKnUSywtyYgvqSxIVbLKK83JQZJBMj05N6MyMjwoJ7LcFqy7tDi1KB6nfC0Ay_Y4og.DHVZjw.PA3epG47smyhQRuUmP2NxwBB0p4'})
Traceback (most recent call last):
  File "/usr/lib/python2.7/site-packages/tornado/web.py", line 1334, in _execute
    result = yield result
  File "/usr/lib/python2.7/site-packages/tornado/gen.py", line 628, in run
    value = future.result()
  File "/usr/lib/python2.7/site-packages/tornado/concurrent.py", line 109, in result
    raise_exc_info(self._exc_info)
  File "/usr/lib/python2.7/site-packages/tornado/gen.py", line 631, in run
    yielded = self.gen.throw(*sys.exc_info())
  File "/usr/lib/python2.7/site-packages/tornado/web.py", line 2172, in get
    yield self.flush()
  File "/usr/lib/python2.7/site-packages/tornado/gen.py", line 628, in run
    value = future.result()
  File "/usr/lib/python2.7/site-packages/tornado/concurrent.py", line 111, in result
    raise self._exception
StreamClosedError
2017-08-15 21:26:58,144 - tornado.general - ERROR - Cannot send error response after headers written
2017-08-15 21:27:51,598 - octoprint.server.util.sockjs - INFO - New connection from client: 192.168.10.10
2017-08-15 21:27:54,626 - octoprint.plugins.softwareupdate - ERROR - Could not check active_filters for updates
Traceback (most recent call last):
  File "/usr/lib/python2.7/site-packages/octoprint/plugins/softwareupdate/__init__.py", line 482, in _get_current_version
    information, is_current = version_checker.get_latest(target, check)
  File "/usr/lib/python2.7/site-packages/octoprint/plugins/softwareupdate/version_checks/github_release.py", line 134, in get_latest
    include_prerelease=include_prerelease)
  File "/usr/lib/python2.7/site-packages/octoprint/plugins/softwareupdate/version_checks/github_release.py", line 19, in _get_latest_release
    r = requests.get(RELEASE_URL.format(user=user, repo=repo))
  File "/usr/lib/python2.7/site-packages/requests/api.py", line 69, in get
    return request('get', url, params=params, **kwargs)
  File "/usr/lib/python2.7/site-packages/requests/api.py", line 50, in request
    response = session.request(method=method, url=url, **kwargs)
  File "/usr/lib/python2.7/site-packages/requests/sessions.py", line 465, in request
    resp = self.send(prep, **send_kwargs)
  File "/usr/lib/python2.7/site-packages/requests/sessions.py", line 573, in send
    r = adapter.send(request, **kwargs)
  File "/usr/lib/python2.7/site-packages/requests/adapters.py", line 415, in send
    raise ConnectionError(err, request=request)
ConnectionError: ('Connection aborted.', gaierror(-2, 'Name or service not known'))
2017-08-15 21:27:54,654 - octoprint.plugins.softwareupdate - ERROR - Could not check touchui for updates
Traceback (most recent call last):
  File "/usr/lib/python2.7/site-packages/octoprint/plugins/softwareupdate/__init__.py", line 482, in _get_current_version
    information, is_current = version_checker.get_latest(target, check)
  File "/usr/lib/python2.7/site-packages/octoprint/plugins/softwareupdate/version_checks/github_release.py", line 134, in get_latest
    include_prerelease=include_prerelease)
  File "/usr/lib/python2.7/site-packages/octoprint/plugins/softwareupdate/version_checks/github_release.py", line 19, in _get_latest_release
    r = requests.get(RELEASE_URL.format(user=user, repo=repo))
  File "/usr/lib/python2.7/site-packages/requests/api.py", line 69, in get
    return request('get', url, params=params, **kwargs)
  File "/usr/lib/python2.7/site-packages/requests/api.py", line 50, in request
    response = session.request(method=method, url=url, **kwargs)
  File "/usr/lib/python2.7/site-packages/requests/sessions.py", line 465, in request
    resp = self.send(prep, **send_kwargs)
  File "/usr/lib/python2.7/site-packages/requests/sessions.py", line 573, in send
    r = adapter.send(request, **kwargs)
  File "/usr/lib/python2.7/site-packages/requests/adapters.py", line 415, in send
    raise ConnectionError(err, request=request)
ConnectionError: ('Connection aborted.', gaierror(-2, 'Name or service not known'))
2017-08-15 21:27:54,668 - octoprint.plugins.softwareupdate - ERROR - Could not check customcontrol for updates
Traceback (most recent call last):
  File "/usr/lib/python2.7/site-packages/octoprint/plugins/softwareupdate/__init__.py", line 482, in _get_current_version
    information, is_current = version_checker.get_latest(target, check)
  File "/usr/lib/python2.7/site-packages/octoprint/plugins/softwareupdate/version_checks/github_release.py", line 134, in get_latest
    include_prerelease=include_prerelease)
  File "/usr/lib/python2.7/site-packages/octoprint/plugins/softwareupdate/version_checks/github_release.py", line 19, in _get_latest_release
    r = requests.get(RELEASE_URL.format(user=user, repo=repo))
  File "/usr/lib/python2.7/site-packages/requests/api.py", line 69, in get
    return request('get', url, params=params, **kwargs)
  File "/usr/lib/python2.7/site-packages/requests/api.py", line 50, in request
    response = session.request(method=method, url=url, **kwargs)
  File "/usr/lib/python2.7/site-packages/requests/sessions.py", line 465, in request
    resp = self.send(prep, **send_kwargs)
  File "/usr/lib/python2.7/site-packages/requests/sessions.py", line 573, in send
    r = adapter.send(request, **kwargs)
  File "/usr/lib/python2.7/site-packages/requests/adapters.py", line 415, in send
    raise ConnectionError(err, request=request)
ConnectionError: ('Connection aborted.', gaierror(-2, 'Name or service not known'))
2017-08-15 21:27:54,683 - octoprint.plugins.softwareupdate - ERROR - Could not check portlister for updates
Traceback (most recent call last):
  File "/usr/lib/python2.7/site-packages/octoprint/plugins/softwareupdate/__init__.py", line 482, in _get_current_version
    information, is_current = version_checker.get_latest(target, check)
  File "/usr/lib/python2.7/site-packages/octoprint/plugins/softwareupdate/version_checks/github_release.py", line 134, in get_latest
    include_prerelease=include_prerelease)
  File "/usr/lib/python2.7/site-packages/octoprint/plugins/softwareupdate/version_checks/github_release.py", line 19, in _get_latest_release
    r = requests.get(RELEASE_URL.format(user=user, repo=repo))
  File "/usr/lib/python2.7/site-packages/requests/api.py", line 69, in get
    return request('get', url, params=params, **kwargs)
  File "/usr/lib/python2.7/site-packages/requests/api.py", line 50, in request
    response = session.request(method=method, url=url, **kwargs)
  File "/usr/lib/python2.7/site-packages/requests/sessions.py", line 465, in request
    resp = self.send(prep, **send_kwargs)
  File "/usr/lib/python2.7/site-packages/requests/sessions.py", line 573, in send
    r = adapter.send(request, **kwargs)
  File "/usr/lib/python2.7/site-packages/requests/adapters.py", line 415, in send
    raise ConnectionError(err, request=request)
ConnectionError: ('Connection aborted.', gaierror(-2, 'Name or service not known'))
2017-08-15 21:27:54,789 - octoprint.plugins.softwareupdate - ERROR - Could not check requestspinner for updates
Traceback (most recent call last):
  File "/usr/lib/python2.7/site-packages/octoprint/plugins/softwareupdate/__init__.py", line 482, in _get_current_version
    information, is_current = version_checker.get_latest(target, check)
  File "/usr/lib/python2.7/site-packages/octoprint/plugins/softwareupdate/version_checks/github_release.py", line 134, in get_latest
    include_prerelease=include_prerelease)
  File "/usr/lib/python2.7/site-packages/octoprint/plugins/softwareupdate/version_checks/github_release.py", line 19, in _get_latest_release
    r = requests.get(RELEASE_URL.format(user=user, repo=repo))
  File "/usr/lib/python2.7/site-packages/requests/api.py", line 69, in get
    return request('get', url, params=params, **kwargs)
  File "/usr/lib/python2.7/site-packages/requests/api.py", line 50, in request
    response = session.request(method=method, url=url, **kwargs)
  File "/usr/lib/python2.7/site-packages/requests/sessions.py", line 465, in request
    resp = self.send(prep, **send_kwargs)
  File "/usr/lib/python2.7/site-packages/requests/sessions.py", line 573, in send
    r = adapter.send(request, **kwargs)
  File "/usr/lib/python2.7/site-packages/requests/adapters.py", line 415, in send
    raise ConnectionError(err, request=request)
ConnectionError: ('Connection aborted.', gaierror(-2, 'Name or service not known'))
2017-08-15 21:27:54,804 - octoprint.plugins.softwareupdate - ERROR - Could not check cost for updates
Traceback (most recent call last):
  File "/usr/lib/python2.7/site-packages/octoprint/plugins/softwareupdate/__init__.py", line 482, in _get_current_version
    information, is_current = version_checker.get_latest(target, check)
  File "/usr/lib/python2.7/site-packages/octoprint/plugins/softwareupdate/version_checks/github_release.py", line 134, in get_latest
    include_prerelease=include_prerelease)
  File "/usr/lib/python2.7/site-packages/octoprint/plugins/softwareupdate/version_checks/github_release.py", line 19, in _get_latest_release
    r = requests.get(RELEASE_URL.format(user=user, repo=repo))
  File "/usr/lib/python2.7/site-packages/requests/api.py", line 69, in get
    return request('get', url, params=params, **kwargs)
  File "/usr/lib/python2.7/site-packages/requests/api.py", line 50, in request
    response = session.request(method=method, url=url, **kwargs)
  File "/usr/lib/python2.7/site-packages/requests/sessions.py", line 465, in request
    resp = self.send(prep, **send_kwargs)
  File "/usr/lib/python2.7/site-packages/requests/sessions.py", line 573, in send
    r = adapter.send(request, **kwargs)
  File "/usr/lib/python2.7/site-packages/requests/adapters.py", line 415, in send
    raise ConnectionError(err, request=request)
ConnectionError: ('Connection aborted.', gaierror(-2, 'Name or service not known'))
2017-08-15 21:27:54,818 - octoprint.plugins.softwareupdate - ERROR - Could not check systemcommandeditor for updates
Traceback (most recent call last):
  File "/usr/lib/python2.7/site-packages/octoprint/plugins/softwareupdate/__init__.py", line 482, in _get_current_version
    information, is_current = version_checker.get_latest(target, check)
  File "/usr/lib/python2.7/site-packages/octoprint/plugins/softwareupdate/version_checks/github_release.py", line 134, in get_latest
    include_prerelease=include_prerelease)
  File "/usr/lib/python2.7/site-packages/octoprint/plugins/softwareupdate/version_checks/github_release.py", line 19, in _get_latest_release
    r = requests.get(RELEASE_URL.format(user=user, repo=repo))
  File "/usr/lib/python2.7/site-packages/requests/api.py", line 69, in get
    return request('get', url, params=params, **kwargs)
  File "/usr/lib/python2.7/site-packages/requests/api.py", line 50, in request
    response = session.request(method=method, url=url, **kwargs)
  File "/usr/lib/python2.7/site-packages/requests/sessions.py", line 465, in request
    resp = self.send(prep, **send_kwargs)
  File "/usr/lib/python2.7/site-packages/requests/sessions.py", line 573, in send
    r = adapter.send(request, **kwargs)
  File "/usr/lib/python2.7/site-packages/requests/adapters.py", line 415, in send
    raise ConnectionError(err, request=request)
ConnectionError: ('Connection aborted.', gaierror(-2, 'Name or service not known'))
2017-08-15 21:27:54,833 - octoprint.plugins.softwareupdate - ERROR - Could not check bqappcompanion for updates
Traceback (most recent call last):
  File "/usr/lib/python2.7/site-packages/octoprint/plugins/softwareupdate/__init__.py", line 482, in _get_current_version
    information, is_current = version_checker.get_latest(target, check)
  File "/usr/lib/python2.7/site-packages/octoprint/plugins/softwareupdate/version_checks/github_release.py", line 134, in get_latest
    include_prerelease=include_prerelease)
  File "/usr/lib/python2.7/site-packages/octoprint/plugins/softwareupdate/version_checks/github_release.py", line 19, in _get_latest_release
    r = requests.get(RELEASE_URL.format(user=user, repo=repo))
  File "/usr/lib/python2.7/site-packages/requests/api.py", line 69, in get
    return request('get', url, params=params, **kwargs)
  File "/usr/lib/python2.7/site-packages/requests/api.py", line 50, in request
    response = session.request(method=method, url=url, **kwargs)
  File "/usr/lib/python2.7/site-packages/requests/sessions.py", line 465, in request
    resp = self.send(prep, **send_kwargs)
  File "/usr/lib/python2.7/site-packages/requests/sessions.py", line 573, in send
    r = adapter.send(request, **kwargs)
  File "/usr/lib/python2.7/site-packages/requests/adapters.py", line 415, in send
    raise ConnectionError(err, request=request)
ConnectionError: ('Connection aborted.', gaierror(-2, 'Name or service not known'))
2017-08-15 21:27:54,930 - octoprint.plugins.softwareupdate - ERROR - Could not check yamlpatcher for updates
Traceback (most recent call last):
  File "/usr/lib/python2.7/site-packages/octoprint/plugins/softwareupdate/__init__.py", line 482, in _get_current_version
    information, is_current = version_checker.get_latest(target, check)
  File "/usr/lib/python2.7/site-packages/octoprint/plugins/softwareupdate/version_checks/github_release.py", line 134, in get_latest
    include_prerelease=include_prerelease)
  File "/usr/lib/python2.7/site-packages/octoprint/plugins/softwareupdate/version_checks/github_release.py", line 19, in _get_latest_release
    r = requests.get(RELEASE_URL.format(user=user, repo=repo))
  File "/usr/lib/python2.7/site-packages/requests/api.py", line 69, in get
    return request('get', url, params=params, **kwargs)
  File "/usr/lib/python2.7/site-packages/requests/api.py", line 50, in request
    response = session.request(method=method, url=url, **kwargs)
  File "/usr/lib/python2.7/site-packages/requests/sessions.py", line 465, in request
    resp = self.send(prep, **send_kwargs)
  File "/usr/lib/python2.7/site-packages/requests/sessions.py", line 573, in send
    r = adapter.send(request, **kwargs)
  File "/usr/lib/python2.7/site-packages/requests/adapters.py", line 415, in send
    raise ConnectionError(err, request=request)
ConnectionError: ('Connection aborted.', gaierror(-2, 'Name or service not known'))
2017-08-15 21:27:55,070 - octoprint.plugins.softwareupdate - INFO - Saved version cache to disk
2017-08-15 21:33:22,707 - octoprint.filemanager.analysis - INFO - Starting analysis of local:minimalistExtruderBase06.0060.dbool_assoprador2.gcode
2017-08-15 21:51:11,541 - octoprint.filemanager.analysis - INFO - Starting analysis of local:minimalistExtruderBase06.0060.dbool_assoprador2.gcode
2017-08-15 21:54:10,599 - octoprint.filemanager.analysis - INFO - Starting analysis of local:minimalistExtruderBase06.0060.dbool_assoprador2.gcode
2017-08-15 21:59:51,353 - octoprint.plugins.portlister - WARNING - Not auto connecting because printer is not closed nor in error state.
2017-08-15 21:59:51,357 - octoprint.plugins.portlister - WARNING - Not auto connecting because printer is not closed nor in error state.
2017-08-15 22:02:57,129 - octoprint.server.util.sockjs - INFO - New connection from client: 192.168.10.10
2017-08-15 22:04:04,864 - octoprint.server.util.sockjs - INFO - Client connection closed: 192.168.10.10
2017-08-15 22:04:06,755 - octoprint.server.util.sockjs - INFO - New connection from client: 192.168.10.10
2017-08-15 22:04:58,807 - octoprint.plugins.portlister - WARNING - Not auto connecting because printer is not closed nor in error state.
2017-08-15 22:04:58,809 - octoprint.plugins.portlister - WARNING - Not auto connecting because printer is not closed nor in error state.
2017-08-15 22:05:02,123 - octoprint.server.util.sockjs - INFO - Client connection closed: 192.168.10.10
2017-08-15 22:05:03,761 - octoprint.server.util.sockjs - INFO - New connection from client: 192.168.10.10
2017-08-15 22:10:31,899 - tornado.application - ERROR - Uncaught exception GET /downloads/files/local/minimalistExtruderBase06.0060.dbool_assoprador2.gcode?ctime=1502858002 (192.168.10.10)
HTTPServerRequest(protocol='http', host='hbot.local:5000', method='GET', uri='/downloads/files/local/minimalistExtruderBase06.0060.dbool_assoprador2.gcode?ctime=1502858002', version='HTTP/1.1', remote_ip='192.168.10.10', headers={'Accept-Language': 'en-US,en;q=0.8,pt-BR;q=0.6,pt;q=0.4', 'Accept-Encoding': 'gzip, deflate', 'X-Api-Key': 'B7F054CC913347B6B5BA232A240C5B0B', 'Host': 'hbot.local:5000', 'Accept': '*/*', 'User-Agent': 'Mozilla/5.0 (X11; Linux x86_64) AppleWebKit/537.36 (KHTML, like Gecko) Chrome/59.0.3071.115 Safari/537.36', 'Dnt': '1', 'Connection': 'keep-alive', 'X-Requested-With': 'XMLHttpRequest', 'Cache-Control': 'no-cache', 'Referer': 'http://hbot.local:5000/', 'Cookie': 'session=.eJyrVopPK0otzlCyKikqTdVRis9MUbKqVlJIUrJS8g_xNYrM9cr2Cw_L9q0KNPXN8sqKzMrIjsr1y_UNya6Ico809XX3rYoKD7VVqtVRykxJzSvJLKnUSywtyYgvqSxIVbLKK83JQZJBMj05N6MyMjwoJ7LcFqy7tDi1KB6nfC0Ay_Y4og.DHVgXg.WawB_4z3uC6WE7ZMdppRhnTczHM'})
Traceback (most recent call last):
  File "/usr/lib/python2.7/site-packages/tornado/web.py", line 1334, in _execute
    result = yield result
  File "/usr/lib/python2.7/site-packages/tornado/gen.py", line 628, in run
    value = future.result()
  File "/usr/lib/python2.7/site-packages/tornado/concurrent.py", line 109, in result
    raise_exc_info(self._exc_info)
  File "/usr/lib/python2.7/site-packages/tornado/gen.py", line 631, in run
    yielded = self.gen.throw(*sys.exc_info())
  File "/usr/lib/python2.7/site-packages/tornado/web.py", line 2172, in get
    yield self.flush()
  File "/usr/lib/python2.7/site-packages/tornado/gen.py", line 628, in run
    value = future.result()
  File "/usr/lib/python2.7/site-packages/tornado/concurrent.py", line 111, in result
    raise self._exception
StreamClosedError
2017-08-15 22:10:31,904 - tornado.general - ERROR - Cannot send error response after headers written
2017-08-15 22:11:34,366 - octoprint.plugins.portlister - WARNING - Not auto connecting because printer is not closed nor in error state.
2017-08-15 22:11:34,369 - octoprint.plugins.portlister - WARNING - Not auto connecting because printer is not closed nor in error state.
2017-08-15 22:11:54,836 - octoprint.timelapse - ERROR - Could not capture image /home/rhradec/.octoprint/timelapse/tmp/minimalistExtruderBase06.0060.dbool_assoprador2_20170815220513-0.jpg from http://hradec.no-ip.org:5001/?action=snapshot
Traceback (most recent call last):
  File "/usr/lib/python2.7/site-packages/octoprint/timelapse.py", line 505, in _perform_capture
    r = requests.get(self._snapshot_url, stream=True)
  File "/usr/lib/python2.7/site-packages/requests/api.py", line 69, in get
    return request('get', url, params=params, **kwargs)
  File "/usr/lib/python2.7/site-packages/requests/api.py", line 50, in request
    response = session.request(method=method, url=url, **kwargs)
  File "/usr/lib/python2.7/site-packages/requests/sessions.py", line 465, in request
    resp = self.send(prep, **send_kwargs)
  File "/usr/lib/python2.7/site-packages/requests/sessions.py", line 573, in send
    r = adapter.send(request, **kwargs)
  File "/usr/lib/python2.7/site-packages/requests/adapters.py", line 415, in send
    raise ConnectionError(err, request=request)
ConnectionError: ('Connection aborted.', BadStatusLine("''",))
2017-08-15 22:11:54,873 - octoprint.timelapse - ERROR - Could not capture image /home/rhradec/.octoprint/timelapse/tmp/minimalistExtruderBase06.0060.dbool_assoprador2_20170815220513-1.jpg from http://hradec.no-ip.org:5001/?action=snapshot
Traceback (most recent call last):
  File "/usr/lib/python2.7/site-packages/octoprint/timelapse.py", line 505, in _perform_capture
    r = requests.get(self._snapshot_url, stream=True)
  File "/usr/lib/python2.7/site-packages/requests/api.py", line 69, in get
    return request('get', url, params=params, **kwargs)
  File "/usr/lib/python2.7/site-packages/requests/api.py", line 50, in request
    response = session.request(method=method, url=url, **kwargs)
  File "/usr/lib/python2.7/site-packages/requests/sessions.py", line 465, in request
    resp = self.send(prep, **send_kwargs)
  File "/usr/lib/python2.7/site-packages/requests/sessions.py", line 573, in send
    r = adapter.send(request, **kwargs)
  File "/usr/lib/python2.7/site-packages/requests/adapters.py", line 415, in send
    raise ConnectionError(err, request=request)
ConnectionError: ('Connection aborted.', error(111, 'Connection refused'))
2017-08-15 22:11:54,900 - octoprint.timelapse - ERROR - Could not capture image /home/rhradec/.octoprint/timelapse/tmp/minimalistExtruderBase06.0060.dbool_assoprador2_20170815220513-2.jpg from http://hradec.no-ip.org:5001/?action=snapshot
Traceback (most recent call last):
  File "/usr/lib/python2.7/site-packages/octoprint/timelapse.py", line 505, in _perform_capture
    r = requests.get(self._snapshot_url, stream=True)
  File "/usr/lib/python2.7/site-packages/requests/api.py", line 69, in get
    return request('get', url, params=params, **kwargs)
  File "/usr/lib/python2.7/site-packages/requests/api.py", line 50, in request
    response = session.request(method=method, url=url, **kwargs)
  File "/usr/lib/python2.7/site-packages/requests/sessions.py", line 465, in request
    resp = self.send(prep, **send_kwargs)
  File "/usr/lib/python2.7/site-packages/requests/sessions.py", line 573, in send
    r = adapter.send(request, **kwargs)
  File "/usr/lib/python2.7/site-packages/requests/adapters.py", line 415, in send
    raise ConnectionError(err, request=request)
ConnectionError: ('Connection aborted.', error(111, 'Connection refused'))
2017-08-15 22:11:54,927 - octoprint.timelapse - ERROR - Could not capture image /home/rhradec/.octoprint/timelapse/tmp/minimalistExtruderBase06.0060.dbool_assoprador2_20170815220513-3.jpg from http://hradec.no-ip.org:5001/?action=snapshot
Traceback (most recent call last):
  File "/usr/lib/python2.7/site-packages/octoprint/timelapse.py", line 505, in _perform_capture
    r = requests.get(self._snapshot_url, stream=True)
  File "/usr/lib/python2.7/site-packages/requests/api.py", line 69, in get
    return request('get', url, params=params, **kwargs)
  File "/usr/lib/python2.7/site-packages/requests/api.py", line 50, in request
    response = session.request(method=method, url=url, **kwargs)
  File "/usr/lib/python2.7/site-packages/requests/sessions.py", line 465, in request
    resp = self.send(prep, **send_kwargs)
  File "/usr/lib/python2.7/site-packages/requests/sessions.py", line 573, in send
    r = adapter.send(request, **kwargs)
  File "/usr/lib/python2.7/site-packages/requests/adapters.py", line 415, in send
    raise ConnectionError(err, request=request)
ConnectionError: ('Connection aborted.', error(111, 'Connection refused'))
2017-08-15 22:11:54,953 - octoprint.timelapse - ERROR - Could not capture image /home/rhradec/.octoprint/timelapse/tmp/minimalistExtruderBase06.0060.dbool_assoprador2_20170815220513-4.jpg from http://hradec.no-ip.org:5001/?action=snapshot
Traceback (most recent call last):
  File "/usr/lib/python2.7/site-packages/octoprint/timelapse.py", line 505, in _perform_capture
    r = requests.get(self._snapshot_url, stream=True)
  File "/usr/lib/python2.7/site-packages/requests/api.py", line 69, in get
    return request('get', url, params=params, **kwargs)
  File "/usr/lib/python2.7/site-packages/requests/api.py", line 50, in request
    response = session.request(method=method, url=url, **kwargs)
  File "/usr/lib/python2.7/site-packages/requests/sessions.py", line 465, in request
    resp = self.send(prep, **send_kwargs)
  File "/usr/lib/python2.7/site-packages/requests/sessions.py", line 573, in send
    r = adapter.send(request, **kwargs)
  File "/usr/lib/python2.7/site-packages/requests/adapters.py", line 415, in send
    raise ConnectionError(err, request=request)
ConnectionError: ('Connection aborted.', error(111, 'Connection refused'))
2017-08-15 22:11:54,979 - octoprint.timelapse - ERROR - Could not capture image /home/rhradec/.octoprint/timelapse/tmp/minimalistExtruderBase06.0060.dbool_assoprador2_20170815220513-5.jpg from http://hradec.no-ip.org:5001/?action=snapshot
Traceback (most recent call last):
  File "/usr/lib/python2.7/site-packages/octoprint/timelapse.py", line 505, in _perform_capture
    r = requests.get(self._snapshot_url, stream=True)
  File "/usr/lib/python2.7/site-packages/requests/api.py", line 69, in get
    return request('get', url, params=params, **kwargs)
  File "/usr/lib/python2.7/site-packages/requests/api.py", line 50, in request
    response = session.request(method=method, url=url, **kwargs)
  File "/usr/lib/python2.7/site-packages/requests/sessions.py", line 465, in request
    resp = self.send(prep, **send_kwargs)
  File "/usr/lib/python2.7/site-packages/requests/sessions.py", line 573, in send
    r = adapter.send(request, **kwargs)
  File "/usr/lib/python2.7/site-packages/requests/adapters.py", line 415, in send
    raise ConnectionError(err, request=request)
ConnectionError: ('Connection aborted.', error(111, 'Connection refused'))
2017-08-15 22:11:55,005 - octoprint.timelapse - ERROR - Could not capture image /home/rhradec/.octoprint/timelapse/tmp/minimalistExtruderBase06.0060.dbool_assoprador2_20170815220513-6.jpg from http://hradec.no-ip.org:5001/?action=snapshot
Traceback (most recent call last):
  File "/usr/lib/python2.7/site-packages/octoprint/timelapse.py", line 505, in _perform_capture
    r = requests.get(self._snapshot_url, stream=True)
  File "/usr/lib/python2.7/site-packages/requests/api.py", line 69, in get
    return request('get', url, params=params, **kwargs)
  File "/usr/lib/python2.7/site-packages/requests/api.py", line 50, in request
    response = session.request(method=method, url=url, **kwargs)
  File "/usr/lib/python2.7/site-packages/requests/sessions.py", line 465, in request
    resp = self.send(prep, **send_kwargs)
  File "/usr/lib/python2.7/site-packages/requests/sessions.py", line 573, in send
    r = adapter.send(request, **kwargs)
  File "/usr/lib/python2.7/site-packages/requests/adapters.py", line 415, in send
    raise ConnectionError(err, request=request)
ConnectionError: ('Connection aborted.', error(111, 'Connection refused'))
2017-08-15 22:11:55,032 - octoprint.timelapse - ERROR - Could not capture image /home/rhradec/.octoprint/timelapse/tmp/minimalistExtruderBase06.0060.dbool_assoprador2_20170815220513-7.jpg from http://hradec.no-ip.org:5001/?action=snapshot
Traceback (most recent call last):
  File "/usr/lib/python2.7/site-packages/octoprint/timelapse.py", line 505, in _perform_capture
    r = requests.get(self._snapshot_url, stream=True)
  File "/usr/lib/python2.7/site-packages/requests/api.py", line 69, in get
    return request('get', url, params=params, **kwargs)
  File "/usr/lib/python2.7/site-packages/requests/api.py", line 50, in request
    response = session.request(method=method, url=url, **kwargs)
  File "/usr/lib/python2.7/site-packages/requests/sessions.py", line 465, in request
    resp = self.send(prep, **send_kwargs)
  File "/usr/lib/python2.7/site-packages/requests/sessions.py", line 573, in send
    r = adapter.send(request, **kwargs)
  File "/usr/lib/python2.7/site-packages/requests/adapters.py", line 415, in send
    raise ConnectionError(err, request=request)
ConnectionError: ('Connection aborted.', error(111, 'Connection refused'))
2017-08-15 22:11:55,058 - octoprint.timelapse - ERROR - Could not capture image /home/rhradec/.octoprint/timelapse/tmp/minimalistExtruderBase06.0060.dbool_assoprador2_20170815220513-8.jpg from http://hradec.no-ip.org:5001/?action=snapshot
Traceback (most recent call last):
  File "/usr/lib/python2.7/site-packages/octoprint/timelapse.py", line 505, in _perform_capture
    r = requests.get(self._snapshot_url, stream=True)
  File "/usr/lib/python2.7/site-packages/requests/api.py", line 69, in get
    return request('get', url, params=params, **kwargs)
  File "/usr/lib/python2.7/site-packages/requests/api.py", line 50, in request
    response = session.request(method=method, url=url, **kwargs)
  File "/usr/lib/python2.7/site-packages/requests/sessions.py", line 465, in request
    resp = self.send(prep, **send_kwargs)
  File "/usr/lib/python2.7/site-packages/requests/sessions.py", line 573, in send
    r = adapter.send(request, **kwargs)
  File "/usr/lib/python2.7/site-packages/requests/adapters.py", line 415, in send
    raise ConnectionError(err, request=request)
ConnectionError: ('Connection aborted.', error(111, 'Connection refused'))
2017-08-15 22:11:55,085 - octoprint.timelapse - ERROR - Could not capture image /home/rhradec/.octoprint/timelapse/tmp/minimalistExtruderBase06.0060.dbool_assoprador2_20170815220513-9.jpg from http://hradec.no-ip.org:5001/?action=snapshot
Traceback (most recent call last):
  File "/usr/lib/python2.7/site-packages/octoprint/timelapse.py", line 505, in _perform_capture
    r = requests.get(self._snapshot_url, stream=True)
  File "/usr/lib/python2.7/site-packages/requests/api.py", line 69, in get
    return request('get', url, params=params, **kwargs)
  File "/usr/lib/python2.7/site-packages/requests/api.py", line 50, in request
    response = session.request(method=method, url=url, **kwargs)
  File "/usr/lib/python2.7/site-packages/requests/sessions.py", line 465, in request
    resp = self.send(prep, **send_kwargs)
  File "/usr/lib/python2.7/site-packages/requests/sessions.py", line 573, in send
    r = adapter.send(request, **kwargs)
  File "/usr/lib/python2.7/site-packages/requests/adapters.py", line 415, in send
    raise ConnectionError(err, request=request)
ConnectionError: ('Connection aborted.', error(111, 'Connection refused'))
2017-08-15 22:11:55,120 - octoprint.timelapse - ERROR - Could not capture image /home/rhradec/.octoprint/timelapse/tmp/minimalistExtruderBase06.0060.dbool_assoprador2_20170815220513-10.jpg from http://hradec.no-ip.org:5001/?action=snapshot
Traceback (most recent call last):
  File "/usr/lib/python2.7/site-packages/octoprint/timelapse.py", line 505, in _perform_capture
    r = requests.get(self._snapshot_url, stream=True)
  File "/usr/lib/python2.7/site-packages/requests/api.py", line 69, in get
    return request('get', url, params=params, **kwargs)
  File "/usr/lib/python2.7/site-packages/requests/api.py", line 50, in request
    response = session.request(method=method, url=url, **kwargs)
  File "/usr/lib/python2.7/site-packages/requests/sessions.py", line 465, in request
    resp = self.send(prep, **send_kwargs)
  File "/usr/lib/python2.7/site-packages/requests/sessions.py", line 573, in send
    r = adapter.send(request, **kwargs)
  File "/usr/lib/python2.7/site-packages/requests/adapters.py", line 415, in send
    raise ConnectionError(err, request=request)
ConnectionError: ('Connection aborted.', error(111, 'Connection refused'))
2017-08-15 22:11:55,146 - octoprint.timelapse - ERROR - Could not capture image /home/rhradec/.octoprint/timelapse/tmp/minimalistExtruderBase06.0060.dbool_assoprador2_20170815220513-11.jpg from http://hradec.no-ip.org:5001/?action=snapshot
Traceback (most recent call last):
  File "/usr/lib/python2.7/site-packages/octoprint/timelapse.py", line 505, in _perform_capture
    r = requests.get(self._snapshot_url, stream=True)
  File "/usr/lib/python2.7/site-packages/requests/api.py", line 69, in get
    return request('get', url, params=params, **kwargs)
  File "/usr/lib/python2.7/site-packages/requests/api.py", line 50, in request
    response = session.request(method=method, url=url, **kwargs)
  File "/usr/lib/python2.7/site-packages/requests/sessions.py", line 465, in request
    resp = self.send(prep, **send_kwargs)
  File "/usr/lib/python2.7/site-packages/requests/sessions.py", line 573, in send
    r = adapter.send(request, **kwargs)
  File "/usr/lib/python2.7/site-packages/requests/adapters.py", line 415, in send
    raise ConnectionError(err, request=request)
ConnectionError: ('Connection aborted.', error(111, 'Connection refused'))
2017-08-15 22:11:55,173 - octoprint.timelapse - ERROR - Could not capture image /home/rhradec/.octoprint/timelapse/tmp/minimalistExtruderBase06.0060.dbool_assoprador2_20170815220513-12.jpg from http://hradec.no-ip.org:5001/?action=snapshot
Traceback (most recent call last):
  File "/usr/lib/python2.7/site-packages/octoprint/timelapse.py", line 505, in _perform_capture
    r = requests.get(self._snapshot_url, stream=True)
  File "/usr/lib/python2.7/site-packages/requests/api.py", line 69, in get
    return request('get', url, params=params, **kwargs)
  File "/usr/lib/python2.7/site-packages/requests/api.py", line 50, in request
    response = session.request(method=method, url=url, **kwargs)
  File "/usr/lib/python2.7/site-packages/requests/sessions.py", line 465, in request
    resp = self.send(prep, **send_kwargs)
  File "/usr/lib/python2.7/site-packages/requests/sessions.py", line 573, in send
    r = adapter.send(request, **kwargs)
  File "/usr/lib/python2.7/site-packages/requests/adapters.py", line 415, in send
    raise ConnectionError(err, request=request)
ConnectionError: ('Connection aborted.', error(111, 'Connection refused'))
2017-08-15 22:11:55,194 - octoprint.timelapse - ERROR - Could not capture image /home/rhradec/.octoprint/timelapse/tmp/minimalistExtruderBase06.0060.dbool_assoprador2_20170815220513-13.jpg from http://hradec.no-ip.org:5001/?action=snapshot
Traceback (most recent call last):
  File "/usr/lib/python2.7/site-packages/octoprint/timelapse.py", line 505, in _perform_capture
    r = requests.get(self._snapshot_url, stream=True)
  File "/usr/lib/python2.7/site-packages/requests/api.py", line 69, in get
    return request('get', url, params=params, **kwargs)
  File "/usr/lib/python2.7/site-packages/requests/api.py", line 50, in request
    response = session.request(method=method, url=url, **kwargs)
  File "/usr/lib/python2.7/site-packages/requests/sessions.py", line 465, in request
    resp = self.send(prep, **send_kwargs)
  File "/usr/lib/python2.7/site-packages/requests/sessions.py", line 573, in send
    r = adapter.send(request, **kwargs)
  File "/usr/lib/python2.7/site-packages/requests/adapters.py", line 415, in send
    raise ConnectionError(err, request=request)
ConnectionError: ('Connection aborted.', error(111, 'Connection refused'))
2017-08-15 22:11:55,213 - octoprint.timelapse - ERROR - Could not capture image /home/rhradec/.octoprint/timelapse/tmp/minimalistExtruderBase06.0060.dbool_assoprador2_20170815220513-14.jpg from http://hradec.no-ip.org:5001/?action=snapshot
Traceback (most recent call last):
  File "/usr/lib/python2.7/site-packages/octoprint/timelapse.py", line 505, in _perform_capture
    r = requests.get(self._snapshot_url, stream=True)
  File "/usr/lib/python2.7/site-packages/requests/api.py", line 69, in get
    return request('get', url, params=params, **kwargs)
  File "/usr/lib/python2.7/site-packages/requests/api.py", line 50, in request
    response = session.request(method=method, url=url, **kwargs)
  File "/usr/lib/python2.7/site-packages/requests/sessions.py", line 465, in request
    resp = self.send(prep, **send_kwargs)
  File "/usr/lib/python2.7/site-packages/requests/sessions.py", line 573, in send
    r = adapter.send(request, **kwargs)
  File "/usr/lib/python2.7/site-packages/requests/adapters.py", line 415, in send
    raise ConnectionError(err, request=request)
ConnectionError: ('Connection aborted.', error(111, 'Connection refused'))
2017-08-15 22:11:55,233 - octoprint.timelapse - ERROR - Could not capture image /home/rhradec/.octoprint/timelapse/tmp/minimalistExtruderBase06.0060.dbool_assoprador2_20170815220513-15.jpg from http://hradec.no-ip.org:5001/?action=snapshot
Traceback (most recent call last):
  File "/usr/lib/python2.7/site-packages/octoprint/timelapse.py", line 505, in _perform_capture
    r = requests.get(self._snapshot_url, stream=True)
  File "/usr/lib/python2.7/site-packages/requests/api.py", line 69, in get
    return request('get', url, params=params, **kwargs)
  File "/usr/lib/python2.7/site-packages/requests/api.py", line 50, in request
    response = session.request(method=method, url=url, **kwargs)
  File "/usr/lib/python2.7/site-packages/requests/sessions.py", line 465, in request
    resp = self.send(prep, **send_kwargs)
  File "/usr/lib/python2.7/site-packages/requests/sessions.py", line 573, in send
    r = adapter.send(request, **kwargs)
  File "/usr/lib/python2.7/site-packages/requests/adapters.py", line 415, in send
    raise ConnectionError(err, request=request)
ConnectionError: ('Connection aborted.', error(111, 'Connection refused'))
2017-08-15 22:11:55,252 - octoprint.timelapse - ERROR - Could not capture image /home/rhradec/.octoprint/timelapse/tmp/minimalistExtruderBase06.0060.dbool_assoprador2_20170815220513-16.jpg from http://hradec.no-ip.org:5001/?action=snapshot
Traceback (most recent call last):
  File "/usr/lib/python2.7/site-packages/octoprint/timelapse.py", line 505, in _perform_capture
    r = requests.get(self._snapshot_url, stream=True)
  File "/usr/lib/python2.7/site-packages/requests/api.py", line 69, in get
    return request('get', url, params=params, **kwargs)
  File "/usr/lib/python2.7/site-packages/requests/api.py", line 50, in request
    response = session.request(method=method, url=url, **kwargs)
  File "/usr/lib/python2.7/site-packages/requests/sessions.py", line 465, in request
    resp = self.send(prep, **send_kwargs)
  File "/usr/lib/python2.7/site-packages/requests/sessions.py", line 573, in send
    r = adapter.send(request, **kwargs)
  File "/usr/lib/python2.7/site-packages/requests/adapters.py", line 415, in send
    raise ConnectionError(err, request=request)
ConnectionError: ('Connection aborted.', error(111, 'Connection refused'))
2017-08-15 22:11:55,271 - octoprint.timelapse - ERROR - Could not capture image /home/rhradec/.octoprint/timelapse/tmp/minimalistExtruderBase06.0060.dbool_assoprador2_20170815220513-17.jpg from http://hradec.no-ip.org:5001/?action=snapshot
Traceback (most recent call last):
  File "/usr/lib/python2.7/site-packages/octoprint/timelapse.py", line 505, in _perform_capture
    r = requests.get(self._snapshot_url, stream=True)
  File "/usr/lib/python2.7/site-packages/requests/api.py", line 69, in get
    return request('get', url, params=params, **kwargs)
  File "/usr/lib/python2.7/site-packages/requests/api.py", line 50, in request
    response = session.request(method=method, url=url, **kwargs)
  File "/usr/lib/python2.7/site-packages/requests/sessions.py", line 465, in request
    resp = self.send(prep, **send_kwargs)
  File "/usr/lib/python2.7/site-packages/requests/sessions.py", line 573, in send
    r = adapter.send(request, **kwargs)
  File "/usr/lib/python2.7/site-packages/requests/adapters.py", line 415, in send
    raise ConnectionError(err, request=request)
ConnectionError: ('Connection aborted.', error(111, 'Connection refused'))
2017-08-15 22:11:55,289 - octoprint.timelapse - ERROR - Could not capture image /home/rhradec/.octoprint/timelapse/tmp/minimalistExtruderBase06.0060.dbool_assoprador2_20170815220513-18.jpg from http://hradec.no-ip.org:5001/?action=snapshot
Traceback (most recent call last):
  File "/usr/lib/python2.7/site-packages/octoprint/timelapse.py", line 505, in _perform_capture
    r = requests.get(self._snapshot_url, stream=True)
  File "/usr/lib/python2.7/site-packages/requests/api.py", line 69, in get
    return request('get', url, params=params, **kwargs)
  File "/usr/lib/python2.7/site-packages/requests/api.py", line 50, in request
    response = session.request(method=method, url=url, **kwargs)
  File "/usr/lib/python2.7/site-packages/requests/sessions.py", line 465, in request
    resp = self.send(prep, **send_kwargs)
  File "/usr/lib/python2.7/site-packages/requests/sessions.py", line 573, in send
    r = adapter.send(request, **kwargs)
  File "/usr/lib/python2.7/site-packages/requests/adapters.py", line 415, in send
    raise ConnectionError(err, request=request)
ConnectionError: ('Connection aborted.', error(111, 'Connection refused'))
2017-08-15 22:11:55,308 - octoprint.timelapse - ERROR - Could not capture image /home/rhradec/.octoprint/timelapse/tmp/minimalistExtruderBase06.0060.dbool_assoprador2_20170815220513-19.jpg from http://hradec.no-ip.org:5001/?action=snapshot
Traceback (most recent call last):
  File "/usr/lib/python2.7/site-packages/octoprint/timelapse.py", line 505, in _perform_capture
    r = requests.get(self._snapshot_url, stream=True)
  File "/usr/lib/python2.7/site-packages/requests/api.py", line 69, in get
    return request('get', url, params=params, **kwargs)
  File "/usr/lib/python2.7/site-packages/requests/api.py", line 50, in request
    response = session.request(method=method, url=url, **kwargs)
  File "/usr/lib/python2.7/site-packages/requests/sessions.py", line 465, in request
    resp = self.send(prep, **send_kwargs)
  File "/usr/lib/python2.7/site-packages/requests/sessions.py", line 573, in send
    r = adapter.send(request, **kwargs)
  File "/usr/lib/python2.7/site-packages/requests/adapters.py", line 415, in send
    raise ConnectionError(err, request=request)
ConnectionError: ('Connection aborted.', error(111, 'Connection refused'))
2017-08-15 22:11:55,326 - octoprint.timelapse - ERROR - Could not capture image /home/rhradec/.octoprint/timelapse/tmp/minimalistExtruderBase06.0060.dbool_assoprador2_20170815220513-20.jpg from http://hradec.no-ip.org:5001/?action=snapshot
Traceback (most recent call last):
  File "/usr/lib/python2.7/site-packages/octoprint/timelapse.py", line 505, in _perform_capture
    r = requests.get(self._snapshot_url, stream=True)
  File "/usr/lib/python2.7/site-packages/requests/api.py", line 69, in get
    return request('get', url, params=params, **kwargs)
  File "/usr/lib/python2.7/site-packages/requests/api.py", line 50, in request
    response = session.request(method=method, url=url, **kwargs)
  File "/usr/lib/python2.7/site-packages/requests/sessions.py", line 465, in request
    resp = self.send(prep, **send_kwargs)
  File "/usr/lib/python2.7/site-packages/requests/sessions.py", line 573, in send
    r = adapter.send(request, **kwargs)
  File "/usr/lib/python2.7/site-packages/requests/adapters.py", line 415, in send
    raise ConnectionError(err, request=request)
ConnectionError: ('Connection aborted.', error(111, 'Connection refused'))
2017-08-15 22:11:55,345 - octoprint.timelapse - ERROR - Could not capture image /home/rhradec/.octoprint/timelapse/tmp/minimalistExtruderBase06.0060.dbool_assoprador2_20170815220513-21.jpg from http://hradec.no-ip.org:5001/?action=snapshot
Traceback (most recent call last):
  File "/usr/lib/python2.7/site-packages/octoprint/timelapse.py", line 505, in _perform_capture
    r = requests.get(self._snapshot_url, stream=True)
  File "/usr/lib/python2.7/site-packages/requests/api.py", line 69, in get
    return request('get', url, params=params, **kwargs)
  File "/usr/lib/python2.7/site-packages/requests/api.py", line 50, in request
    response = session.request(method=method, url=url, **kwargs)
  File "/usr/lib/python2.7/site-packages/requests/sessions.py", line 465, in request
    resp = self.send(prep, **send_kwargs)
  File "/usr/lib/python2.7/site-packages/requests/sessions.py", line 573, in send
    r = adapter.send(request, **kwargs)
  File "/usr/lib/python2.7/site-packages/requests/adapters.py", line 415, in send
    raise ConnectionError(err, request=request)
ConnectionError: ('Connection aborted.', error(111, 'Connection refused'))
2017-08-15 22:11:55,364 - octoprint.timelapse - ERROR - Could not capture image /home/rhradec/.octoprint/timelapse/tmp/minimalistExtruderBase06.0060.dbool_assoprador2_20170815220513-22.jpg from http://hradec.no-ip.org:5001/?action=snapshot
Traceback (most recent call last):
  File "/usr/lib/python2.7/site-packages/octoprint/timelapse.py", line 505, in _perform_capture
    r = requests.get(self._snapshot_url, stream=True)
  File "/usr/lib/python2.7/site-packages/requests/api.py", line 69, in get
    return request('get', url, params=params, **kwargs)
  File "/usr/lib/python2.7/site-packages/requests/api.py", line 50, in request
    response = session.request(method=method, url=url, **kwargs)
  File "/usr/lib/python2.7/site-packages/requests/sessions.py", line 465, in request
    resp = self.send(prep, **send_kwargs)
  File "/usr/lib/python2.7/site-packages/requests/sessions.py", line 573, in send
    r = adapter.send(request, **kwargs)
  File "/usr/lib/python2.7/site-packages/requests/adapters.py", line 415, in send
    raise ConnectionError(err, request=request)
ConnectionError: ('Connection aborted.', error(111, 'Connection refused'))
2017-08-15 22:11:55,390 - octoprint.timelapse - ERROR - Could not capture image /home/rhradec/.octoprint/timelapse/tmp/minimalistExtruderBase06.0060.dbool_assoprador2_20170815220513-23.jpg from http://hradec.no-ip.org:5001/?action=snapshot
Traceback (most recent call last):
  File "/usr/lib/python2.7/site-packages/octoprint/timelapse.py", line 505, in _perform_capture
    r = requests.get(self._snapshot_url, stream=True)
  File "/usr/lib/python2.7/site-packages/requests/api.py", line 69, in get
    return request('get', url, params=params, **kwargs)
  File "/usr/lib/python2.7/site-packages/requests/api.py", line 50, in request
    response = session.request(method=method, url=url, **kwargs)
  File "/usr/lib/python2.7/site-packages/requests/sessions.py", line 465, in request
    resp = self.send(prep, **send_kwargs)
  File "/usr/lib/python2.7/site-packages/requests/sessions.py", line 573, in send
    r = adapter.send(request, **kwargs)
  File "/usr/lib/python2.7/site-packages/requests/adapters.py", line 415, in send
    raise ConnectionError(err, request=request)
ConnectionError: ('Connection aborted.', error(111, 'Connection refused'))
2017-08-15 22:11:55,416 - octoprint.timelapse - ERROR - Could not capture image /home/rhradec/.octoprint/timelapse/tmp/minimalistExtruderBase06.0060.dbool_assoprador2_20170815220513-24.jpg from http://hradec.no-ip.org:5001/?action=snapshot
Traceback (most recent call last):
  File "/usr/lib/python2.7/site-packages/octoprint/timelapse.py", line 505, in _perform_capture
    r = requests.get(self._snapshot_url, stream=True)
  File "/usr/lib/python2.7/site-packages/requests/api.py", line 69, in get
    return request('get', url, params=params, **kwargs)
  File "/usr/lib/python2.7/site-packages/requests/api.py", line 50, in request
    response = session.request(method=method, url=url, **kwargs)
  File "/usr/lib/python2.7/site-packages/requests/sessions.py", line 465, in request
    resp = self.send(prep, **send_kwargs)
  File "/usr/lib/python2.7/site-packages/requests/sessions.py", line 573, in send
    r = adapter.send(request, **kwargs)
  File "/usr/lib/python2.7/site-packages/requests/adapters.py", line 415, in send
    raise ConnectionError(err, request=request)
ConnectionError: ('Connection aborted.', error(111, 'Connection refused'))
2017-08-15 22:11:55,439 - octoprint.timelapse - ERROR - Could not capture image /home/rhradec/.octoprint/timelapse/tmp/minimalistExtruderBase06.0060.dbool_assoprador2_20170815220513-25.jpg from http://hradec.no-ip.org:5001/?action=snapshot
Traceback (most recent call last):
  File "/usr/lib/python2.7/site-packages/octoprint/timelapse.py", line 505, in _perform_capture
    r = requests.get(self._snapshot_url, stream=True)
  File "/usr/lib/python2.7/site-packages/requests/api.py", line 69, in get
    return request('get', url, params=params, **kwargs)
  File "/usr/lib/python2.7/site-packages/requests/api.py", line 50, in request
    response = session.request(method=method, url=url, **kwargs)
  File "/usr/lib/python2.7/site-packages/requests/sessions.py", line 465, in request
    resp = self.send(prep, **send_kwargs)
  File "/usr/lib/python2.7/site-packages/requests/sessions.py", line 573, in send
    r = adapter.send(request, **kwargs)
  File "/usr/lib/python2.7/site-packages/requests/adapters.py", line 415, in send
    raise ConnectionError(err, request=request)
ConnectionError: ('Connection aborted.', error(111, 'Connection refused'))
2017-08-15 22:11:55,462 - octoprint.timelapse - ERROR - Could not capture image /home/rhradec/.octoprint/timelapse/tmp/minimalistExtruderBase06.0060.dbool_assoprador2_20170815220513-26.jpg from http://hradec.no-ip.org:5001/?action=snapshot
Traceback (most recent call last):
  File "/usr/lib/python2.7/site-packages/octoprint/timelapse.py", line 505, in _perform_capture
    r = requests.get(self._snapshot_url, stream=True)
  File "/usr/lib/python2.7/site-packages/requests/api.py", line 69, in get
    return request('get', url, params=params, **kwargs)
  File "/usr/lib/python2.7/site-packages/requests/api.py", line 50, in request
    response = session.request(method=method, url=url, **kwargs)
  File "/usr/lib/python2.7/site-packages/requests/sessions.py", line 465, in request
    resp = self.send(prep, **send_kwargs)
  File "/usr/lib/python2.7/site-packages/requests/sessions.py", line 573, in send
    r = adapter.send(request, **kwargs)
  File "/usr/lib/python2.7/site-packages/requests/adapters.py", line 415, in send
    raise ConnectionError(err, request=request)
ConnectionError: ('Connection aborted.', error(111, 'Connection refused'))
2017-08-15 22:11:55,483 - octoprint.timelapse - ERROR - Could not capture image /home/rhradec/.octoprint/timelapse/tmp/minimalistExtruderBase06.0060.dbool_assoprador2_20170815220513-27.jpg from http://hradec.no-ip.org:5001/?action=snapshot
Traceback (most recent call last):
  File "/usr/lib/python2.7/site-packages/octoprint/timelapse.py", line 505, in _perform_capture
    r = requests.get(self._snapshot_url, stream=True)
  File "/usr/lib/python2.7/site-packages/requests/api.py", line 69, in get
    return request('get', url, params=params, **kwargs)
  File "/usr/lib/python2.7/site-packages/requests/api.py", line 50, in request
    response = session.request(method=method, url=url, **kwargs)
  File "/usr/lib/python2.7/site-packages/requests/sessions.py", line 465, in request
    resp = self.send(prep, **send_kwargs)
  File "/usr/lib/python2.7/site-packages/requests/sessions.py", line 573, in send
    r = adapter.send(request, **kwargs)
  File "/usr/lib/python2.7/site-packages/requests/adapters.py", line 415, in send
    raise ConnectionError(err, request=request)
ConnectionError: ('Connection aborted.', error(111, 'Connection refused'))
2017-08-15 22:11:55,503 - octoprint.timelapse - ERROR - Could not capture image /home/rhradec/.octoprint/timelapse/tmp/minimalistExtruderBase06.0060.dbool_assoprador2_20170815220513-28.jpg from http://hradec.no-ip.org:5001/?action=snapshot
Traceback (most recent call last):
  File "/usr/lib/python2.7/site-packages/octoprint/timelapse.py", line 505, in _perform_capture
    r = requests.get(self._snapshot_url, stream=True)
  File "/usr/lib/python2.7/site-packages/requests/api.py", line 69, in get
    return request('get', url, params=params, **kwargs)
  File "/usr/lib/python2.7/site-packages/requests/api.py", line 50, in request
    response = session.request(method=method, url=url, **kwargs)
  File "/usr/lib/python2.7/site-packages/requests/sessions.py", line 465, in request
    resp = self.send(prep, **send_kwargs)
  File "/usr/lib/python2.7/site-packages/requests/sessions.py", line 573, in send
    r = adapter.send(request, **kwargs)
  File "/usr/lib/python2.7/site-packages/requests/adapters.py", line 415, in send
    raise ConnectionError(err, request=request)
ConnectionError: ('Connection aborted.', error(111, 'Connection refused'))
2017-08-15 22:11:55,523 - octoprint.timelapse - ERROR - Could not capture image /home/rhradec/.octoprint/timelapse/tmp/minimalistExtruderBase06.0060.dbool_assoprador2_20170815220513-29.jpg from http://hradec.no-ip.org:5001/?action=snapshot
Traceback (most recent call last):
  File "/usr/lib/python2.7/site-packages/octoprint/timelapse.py", line 505, in _perform_capture
    r = requests.get(self._snapshot_url, stream=True)
  File "/usr/lib/python2.7/site-packages/requests/api.py", line 69, in get
    return request('get', url, params=params, **kwargs)
  File "/usr/lib/python2.7/site-packages/requests/api.py", line 50, in request
    response = session.request(method=method, url=url, **kwargs)
  File "/usr/lib/python2.7/site-packages/requests/sessions.py", line 465, in request
    resp = self.send(prep, **send_kwargs)
  File "/usr/lib/python2.7/site-packages/requests/sessions.py", line 573, in send
    r = adapter.send(request, **kwargs)
  File "/usr/lib/python2.7/site-packages/requests/adapters.py", line 415, in send
    raise ConnectionError(err, request=request)
ConnectionError: ('Connection aborted.', error(111, 'Connection refused'))
2017-08-15 22:11:55,545 - octoprint.timelapse - ERROR - Could not capture image /home/rhradec/.octoprint/timelapse/tmp/minimalistExtruderBase06.0060.dbool_assoprador2_20170815220513-30.jpg from http://hradec.no-ip.org:5001/?action=snapshot
Traceback (most recent call last):
  File "/usr/lib/python2.7/site-packages/octoprint/timelapse.py", line 505, in _perform_capture
    r = requests.get(self._snapshot_url, stream=True)
  File "/usr/lib/python2.7/site-packages/requests/api.py", line 69, in get
    return request('get', url, params=params, **kwargs)
  File "/usr/lib/python2.7/site-packages/requests/api.py", line 50, in request
    response = session.request(method=method, url=url, **kwargs)
  File "/usr/lib/python2.7/site-packages/requests/sessions.py", line 465, in request
    resp = self.send(prep, **send_kwargs)
  File "/usr/lib/python2.7/site-packages/requests/sessions.py", line 573, in send
    r = adapter.send(request, **kwargs)
  File "/usr/lib/python2.7/site-packages/requests/adapters.py", line 415, in send
    raise ConnectionError(err, request=request)
ConnectionError: ('Connection aborted.', error(111, 'Connection refused'))
2017-08-15 22:11:55,566 - octoprint.timelapse - ERROR - Could not capture image /home/rhradec/.octoprint/timelapse/tmp/minimalistExtruderBase06.0060.dbool_assoprador2_20170815220513-31.jpg from http://hradec.no-ip.org:5001/?action=snapshot
Traceback (most recent call last):
  File "/usr/lib/python2.7/site-packages/octoprint/timelapse.py", line 505, in _perform_capture
    r = requests.get(self._snapshot_url, stream=True)
  File "/usr/lib/python2.7/site-packages/requests/api.py", line 69, in get
    return request('get', url, params=params, **kwargs)
  File "/usr/lib/python2.7/site-packages/requests/api.py", line 50, in request
    response = session.request(method=method, url=url, **kwargs)
  File "/usr/lib/python2.7/site-packages/requests/sessions.py", line 465, in request
    resp = self.send(prep, **send_kwargs)
  File "/usr/lib/python2.7/site-packages/requests/sessions.py", line 573, in send
    r = adapter.send(request, **kwargs)
  File "/usr/lib/python2.7/site-packages/requests/adapters.py", line 415, in send
    raise ConnectionError(err, request=request)
ConnectionError: ('Connection aborted.', error(111, 'Connection refused'))
2017-08-15 22:11:55,590 - octoprint.timelapse - ERROR - Could not capture image /home/rhradec/.octoprint/timelapse/tmp/minimalistExtruderBase06.0060.dbool_assoprador2_20170815220513-32.jpg from http://hradec.no-ip.org:5001/?action=snapshot
Traceback (most recent call last):
  File "/usr/lib/python2.7/site-packages/octoprint/timelapse.py", line 505, in _perform_capture
    r = requests.get(self._snapshot_url, stream=True)
  File "/usr/lib/python2.7/site-packages/requests/api.py", line 69, in get
    return request('get', url, params=params, **kwargs)
  File "/usr/lib/python2.7/site-packages/requests/api.py", line 50, in request
    response = session.request(method=method, url=url, **kwargs)
  File "/usr/lib/python2.7/site-packages/requests/sessions.py", line 465, in request
    resp = self.send(prep, **send_kwargs)
  File "/usr/lib/python2.7/site-packages/requests/sessions.py", line 573, in send
    r = adapter.send(request, **kwargs)
  File "/usr/lib/python2.7/site-packages/requests/adapters.py", line 415, in send
    raise ConnectionError(err, request=request)
ConnectionError: ('Connection aborted.', error(111, 'Connection refused'))
2017-08-15 22:11:55,617 - octoprint.timelapse - ERROR - Could not capture image /home/rhradec/.octoprint/timelapse/tmp/minimalistExtruderBase06.0060.dbool_assoprador2_20170815220513-33.jpg from http://hradec.no-ip.org:5001/?action=snapshot
Traceback (most recent call last):
  File "/usr/lib/python2.7/site-packages/octoprint/timelapse.py", line 505, in _perform_capture
    r = requests.get(self._snapshot_url, stream=True)
  File "/usr/lib/python2.7/site-packages/requests/api.py", line 69, in get
    return request('get', url, params=params, **kwargs)
  File "/usr/lib/python2.7/site-packages/requests/api.py", line 50, in request
    response = session.request(method=method, url=url, **kwargs)
  File "/usr/lib/python2.7/site-packages/requests/sessions.py", line 465, in request
    resp = self.send(prep, **send_kwargs)
  File "/usr/lib/python2.7/site-packages/requests/sessions.py", line 573, in send
    r = adapter.send(request, **kwargs)
  File "/usr/lib/python2.7/site-packages/requests/adapters.py", line 415, in send
    raise ConnectionError(err, request=request)
ConnectionError: ('Connection aborted.', error(111, 'Connection refused'))
2017-08-15 22:11:55,638 - octoprint.timelapse - ERROR - Could not capture image /home/rhradec/.octoprint/timelapse/tmp/minimalistExtruderBase06.0060.dbool_assoprador2_20170815220513-34.jpg from http://hradec.no-ip.org:5001/?action=snapshot
Traceback (most recent call last):
  File "/usr/lib/python2.7/site-packages/octoprint/timelapse.py", line 505, in _perform_capture
    r = requests.get(self._snapshot_url, stream=True)
  File "/usr/lib/python2.7/site-packages/requests/api.py", line 69, in get
    return request('get', url, params=params, **kwargs)
  File "/usr/lib/python2.7/site-packages/requests/api.py", line 50, in request
    response = session.request(method=method, url=url, **kwargs)
  File "/usr/lib/python2.7/site-packages/requests/sessions.py", line 465, in request
    resp = self.send(prep, **send_kwargs)
  File "/usr/lib/python2.7/site-packages/requests/sessions.py", line 573, in send
    r = adapter.send(request, **kwargs)
  File "/usr/lib/python2.7/site-packages/requests/adapters.py", line 415, in send
    raise ConnectionError(err, request=request)
ConnectionError: ('Connection aborted.', error(111, 'Connection refused'))
2017-08-15 22:11:55,659 - octoprint.timelapse - ERROR - Could not capture image /home/rhradec/.octoprint/timelapse/tmp/minimalistExtruderBase06.0060.dbool_assoprador2_20170815220513-35.jpg from http://hradec.no-ip.org:5001/?action=snapshot
Traceback (most recent call last):
  File "/usr/lib/python2.7/site-packages/octoprint/timelapse.py", line 505, in _perform_capture
    r = requests.get(self._snapshot_url, stream=True)
  File "/usr/lib/python2.7/site-packages/requests/api.py", line 69, in get
    return request('get', url, params=params, **kwargs)
  File "/usr/lib/python2.7/site-packages/requests/api.py", line 50, in request
    response = session.request(method=method, url=url, **kwargs)
  File "/usr/lib/python2.7/site-packages/requests/sessions.py", line 465, in request
    resp = self.send(prep, **send_kwargs)
  File "/usr/lib/python2.7/site-packages/requests/sessions.py", line 573, in send
    r = adapter.send(request, **kwargs)
  File "/usr/lib/python2.7/site-packages/requests/adapters.py", line 415, in send
    raise ConnectionError(err, request=request)
ConnectionError: ('Connection aborted.', error(111, 'Connection refused'))
2017-08-15 22:11:55,679 - octoprint.timelapse - ERROR - Could not capture image /home/rhradec/.octoprint/timelapse/tmp/minimalistExtruderBase06.0060.dbool_assoprador2_20170815220513-36.jpg from http://hradec.no-ip.org:5001/?action=snapshot
Traceback (most recent call last):
  File "/usr/lib/python2.7/site-packages/octoprint/timelapse.py", line 505, in _perform_capture
    r = requests.get(self._snapshot_url, stream=True)
  File "/usr/lib/python2.7/site-packages/requests/api.py", line 69, in get
    return request('get', url, params=params, **kwargs)
  File "/usr/lib/python2.7/site-packages/requests/api.py", line 50, in request
    response = session.request(method=method, url=url, **kwargs)
  File "/usr/lib/python2.7/site-packages/requests/sessions.py", line 465, in request
    resp = self.send(prep, **send_kwargs)
  File "/usr/lib/python2.7/site-packages/requests/sessions.py", line 573, in send
    r = adapter.send(request, **kwargs)
  File "/usr/lib/python2.7/site-packages/requests/adapters.py", line 415, in send
    raise ConnectionError(err, request=request)
ConnectionError: ('Connection aborted.', error(111, 'Connection refused'))
2017-08-15 22:11:55,699 - octoprint.timelapse - ERROR - Could not capture image /home/rhradec/.octoprint/timelapse/tmp/minimalistExtruderBase06.0060.dbool_assoprador2_20170815220513-37.jpg from http://hradec.no-ip.org:5001/?action=snapshot
Traceback (most recent call last):
  File "/usr/lib/python2.7/site-packages/octoprint/timelapse.py", line 505, in _perform_capture
    r = requests.get(self._snapshot_url, stream=True)
  File "/usr/lib/python2.7/site-packages/requests/api.py", line 69, in get
    return request('get', url, params=params, **kwargs)
  File "/usr/lib/python2.7/site-packages/requests/api.py", line 50, in request
    response = session.request(method=method, url=url, **kwargs)
  File "/usr/lib/python2.7/site-packages/requests/sessions.py", line 465, in request
    resp = self.send(prep, **send_kwargs)
  File "/usr/lib/python2.7/site-packages/requests/sessions.py", line 573, in send
    r = adapter.send(request, **kwargs)
  File "/usr/lib/python2.7/site-packages/requests/adapters.py", line 415, in send
    raise ConnectionError(err, request=request)
ConnectionError: ('Connection aborted.', error(111, 'Connection refused'))
2017-08-15 22:11:55,719 - octoprint.timelapse - ERROR - Could not capture image /home/rhradec/.octoprint/timelapse/tmp/minimalistExtruderBase06.0060.dbool_assoprador2_20170815220513-38.jpg from http://hradec.no-ip.org:5001/?action=snapshot
Traceback (most recent call last):
  File "/usr/lib/python2.7/site-packages/octoprint/timelapse.py", line 505, in _perform_capture
    r = requests.get(self._snapshot_url, stream=True)
  File "/usr/lib/python2.7/site-packages/requests/api.py", line 69, in get
    return request('get', url, params=params, **kwargs)
  File "/usr/lib/python2.7/site-packages/requests/api.py", line 50, in request
    response = session.request(method=method, url=url, **kwargs)
  File "/usr/lib/python2.7/site-packages/requests/sessions.py", line 465, in request
    resp = self.send(prep, **send_kwargs)
  File "/usr/lib/python2.7/site-packages/requests/sessions.py", line 573, in send
    r = adapter.send(request, **kwargs)
  File "/usr/lib/python2.7/site-packages/requests/adapters.py", line 415, in send
    raise ConnectionError(err, request=request)
ConnectionError: ('Connection aborted.', error(111, 'Connection refused'))
2017-08-15 22:11:55,740 - octoprint.timelapse - ERROR - Could not capture image /home/rhradec/.octoprint/timelapse/tmp/minimalistExtruderBase06.0060.dbool_assoprador2_20170815220513-39.jpg from http://hradec.no-ip.org:5001/?action=snapshot
Traceback (most recent call last):
  File "/usr/lib/python2.7/site-packages/octoprint/timelapse.py", line 505, in _perform_capture
    r = requests.get(self._snapshot_url, stream=True)
  File "/usr/lib/python2.7/site-packages/requests/api.py", line 69, in get
    return request('get', url, params=params, **kwargs)
  File "/usr/lib/python2.7/site-packages/requests/api.py", line 50, in request
    response = session.request(method=method, url=url, **kwargs)
  File "/usr/lib/python2.7/site-packages/requests/sessions.py", line 465, in request
    resp = self.send(prep, **send_kwargs)
  File "/usr/lib/python2.7/site-packages/requests/sessions.py", line 573, in send
    r = adapter.send(request, **kwargs)
  File "/usr/lib/python2.7/site-packages/requests/adapters.py", line 415, in send
    raise ConnectionError(err, request=request)
ConnectionError: ('Connection aborted.', error(111, 'Connection refused'))
2017-08-15 22:11:55,762 - octoprint.timelapse - ERROR - Could not capture image /home/rhradec/.octoprint/timelapse/tmp/minimalistExtruderBase06.0060.dbool_assoprador2_20170815220513-40.jpg from http://hradec.no-ip.org:5001/?action=snapshot
Traceback (most recent call last):
  File "/usr/lib/python2.7/site-packages/octoprint/timelapse.py", line 505, in _perform_capture
    r = requests.get(self._snapshot_url, stream=True)
  File "/usr/lib/python2.7/site-packages/requests/api.py", line 69, in get
    return request('get', url, params=params, **kwargs)
  File "/usr/lib/python2.7/site-packages/requests/api.py", line 50, in request
    response = session.request(method=method, url=url, **kwargs)
  File "/usr/lib/python2.7/site-packages/requests/sessions.py", line 465, in request
    resp = self.send(prep, **send_kwargs)
  File "/usr/lib/python2.7/site-packages/requests/sessions.py", line 573, in send
    r = adapter.send(request, **kwargs)
  File "/usr/lib/python2.7/site-packages/requests/adapters.py", line 415, in send
    raise ConnectionError(err, request=request)
ConnectionError: ('Connection aborted.', error(111, 'Connection refused'))
2017-08-15 22:11:55,785 - octoprint.timelapse - ERROR - Could not capture image /home/rhradec/.octoprint/timelapse/tmp/minimalistExtruderBase06.0060.dbool_assoprador2_20170815220513-41.jpg from http://hradec.no-ip.org:5001/?action=snapshot
Traceback (most recent call last):
  File "/usr/lib/python2.7/site-packages/octoprint/timelapse.py", line 505, in _perform_capture
    r = requests.get(self._snapshot_url, stream=True)
  File "/usr/lib/python2.7/site-packages/requests/api.py", line 69, in get
    return request('get', url, params=params, **kwargs)
  File "/usr/lib/python2.7/site-packages/requests/api.py", line 50, in request
    response = session.request(method=method, url=url, **kwargs)
  File "/usr/lib/python2.7/site-packages/requests/sessions.py", line 465, in request
    resp = self.send(prep, **send_kwargs)
  File "/usr/lib/python2.7/site-packages/requests/sessions.py", line 573, in send
    r = adapter.send(request, **kwargs)
  File "/usr/lib/python2.7/site-packages/requests/adapters.py", line 415, in send
    raise ConnectionError(err, request=request)
ConnectionError: ('Connection aborted.', error(111, 'Connection refused'))
2017-08-15 22:11:55,804 - octoprint.timelapse - ERROR - Could not capture image /home/rhradec/.octoprint/timelapse/tmp/minimalistExtruderBase06.0060.dbool_assoprador2_20170815220513-42.jpg from http://hradec.no-ip.org:5001/?action=snapshot
Traceback (most recent call last):
  File "/usr/lib/python2.7/site-packages/octoprint/timelapse.py", line 505, in _perform_capture
    r = requests.get(self._snapshot_url, stream=True)
  File "/usr/lib/python2.7/site-packages/requests/api.py", line 69, in get
    return request('get', url, params=params, **kwargs)
  File "/usr/lib/python2.7/site-packages/requests/api.py", line 50, in request
    response = session.request(method=method, url=url, **kwargs)
  File "/usr/lib/python2.7/site-packages/requests/sessions.py", line 465, in request
    resp = self.send(prep, **send_kwargs)
  File "/usr/lib/python2.7/site-packages/requests/sessions.py", line 573, in send
    r = adapter.send(request, **kwargs)
  File "/usr/lib/python2.7/site-packages/requests/adapters.py", line 415, in send
    raise ConnectionError(err, request=request)
ConnectionError: ('Connection aborted.', error(111, 'Connection refused'))
2017-08-15 22:11:55,823 - octoprint.timelapse - ERROR - Could not capture image /home/rhradec/.octoprint/timelapse/tmp/minimalistExtruderBase06.0060.dbool_assoprador2_20170815220513-43.jpg from http://hradec.no-ip.org:5001/?action=snapshot
Traceback (most recent call last):
  File "/usr/lib/python2.7/site-packages/octoprint/timelapse.py", line 505, in _perform_capture
    r = requests.get(self._snapshot_url, stream=True)
  File "/usr/lib/python2.7/site-packages/requests/api.py", line 69, in get
    return request('get', url, params=params, **kwargs)
  File "/usr/lib/python2.7/site-packages/requests/api.py", line 50, in request
    response = session.request(method=method, url=url, **kwargs)
  File "/usr/lib/python2.7/site-packages/requests/sessions.py", line 465, in request
    resp = self.send(prep, **send_kwargs)
  File "/usr/lib/python2.7/site-packages/requests/sessions.py", line 573, in send
    r = adapter.send(request, **kwargs)
  File "/usr/lib/python2.7/site-packages/requests/adapters.py", line 415, in send
    raise ConnectionError(err, request=request)
ConnectionError: ('Connection aborted.', error(111, 'Connection refused'))
2017-08-15 22:11:55,842 - octoprint.timelapse - ERROR - Could not capture image /home/rhradec/.octoprint/timelapse/tmp/minimalistExtruderBase06.0060.dbool_assoprador2_20170815220513-44.jpg from http://hradec.no-ip.org:5001/?action=snapshot
Traceback (most recent call last):
  File "/usr/lib/python2.7/site-packages/octoprint/timelapse.py", line 505, in _perform_capture
    r = requests.get(self._snapshot_url, stream=True)
  File "/usr/lib/python2.7/site-packages/requests/api.py", line 69, in get
    return request('get', url, params=params, **kwargs)
  File "/usr/lib/python2.7/site-packages/requests/api.py", line 50, in request
    response = session.request(method=method, url=url, **kwargs)
  File "/usr/lib/python2.7/site-packages/requests/sessions.py", line 465, in request
    resp = self.send(prep, **send_kwargs)
  File "/usr/lib/python2.7/site-packages/requests/sessions.py", line 573, in send
    r = adapter.send(request, **kwargs)
  File "/usr/lib/python2.7/site-packages/requests/adapters.py", line 415, in send
    raise ConnectionError(err, request=request)
ConnectionError: ('Connection aborted.', error(111, 'Connection refused'))
2017-08-15 22:11:55,861 - octoprint.timelapse - ERROR - Could not capture image /home/rhradec/.octoprint/timelapse/tmp/minimalistExtruderBase06.0060.dbool_assoprador2_20170815220513-45.jpg from http://hradec.no-ip.org:5001/?action=snapshot
Traceback (most recent call last):
  File "/usr/lib/python2.7/site-packages/octoprint/timelapse.py", line 505, in _perform_capture
    r = requests.get(self._snapshot_url, stream=True)
  File "/usr/lib/python2.7/site-packages/requests/api.py", line 69, in get
    return request('get', url, params=params, **kwargs)
  File "/usr/lib/python2.7/site-packages/requests/api.py", line 50, in request
    response = session.request(method=method, url=url, **kwargs)
  File "/usr/lib/python2.7/site-packages/requests/sessions.py", line 465, in request
    resp = self.send(prep, **send_kwargs)
  File "/usr/lib/python2.7/site-packages/requests/sessions.py", line 573, in send
    r = adapter.send(request, **kwargs)
  File "/usr/lib/python2.7/site-packages/requests/adapters.py", line 415, in send
    raise ConnectionError(err, request=request)
ConnectionError: ('Connection aborted.', error(111, 'Connection refused'))
2017-08-15 22:11:55,883 - octoprint.timelapse - ERROR - Could not capture image /home/rhradec/.octoprint/timelapse/tmp/minimalistExtruderBase06.0060.dbool_assoprador2_20170815220513-46.jpg from http://hradec.no-ip.org:5001/?action=snapshot
Traceback (most recent call last):
  File "/usr/lib/python2.7/site-packages/octoprint/timelapse.py", line 505, in _perform_capture
    r = requests.get(self._snapshot_url, stream=True)
  File "/usr/lib/python2.7/site-packages/requests/api.py", line 69, in get
    return request('get', url, params=params, **kwargs)
  File "/usr/lib/python2.7/site-packages/requests/api.py", line 50, in request
    response = session.request(method=method, url=url, **kwargs)
  File "/usr/lib/python2.7/site-packages/requests/sessions.py", line 465, in request
    resp = self.send(prep, **send_kwargs)
  File "/usr/lib/python2.7/site-packages/requests/sessions.py", line 573, in send
    r = adapter.send(request, **kwargs)
  File "/usr/lib/python2.7/site-packages/requests/adapters.py", line 415, in send
    raise ConnectionError(err, request=request)
ConnectionError: ('Connection aborted.', error(111, 'Connection refused'))
2017-08-15 22:11:55,903 - octoprint.timelapse - ERROR - Could not capture image /home/rhradec/.octoprint/timelapse/tmp/minimalistExtruderBase06.0060.dbool_assoprador2_20170815220513-47.jpg from http://hradec.no-ip.org:5001/?action=snapshot
Traceback (most recent call last):
  File "/usr/lib/python2.7/site-packages/octoprint/timelapse.py", line 505, in _perform_capture
    r = requests.get(self._snapshot_url, stream=True)
  File "/usr/lib/python2.7/site-packages/requests/api.py", line 69, in get
    return request('get', url, params=params, **kwargs)
  File "/usr/lib/python2.7/site-packages/requests/api.py", line 50, in request
    response = session.request(method=method, url=url, **kwargs)
  File "/usr/lib/python2.7/site-packages/requests/sessions.py", line 465, in request
    resp = self.send(prep, **send_kwargs)
  File "/usr/lib/python2.7/site-packages/requests/sessions.py", line 573, in send
    r = adapter.send(request, **kwargs)
  File "/usr/lib/python2.7/site-packages/requests/adapters.py", line 415, in send
    raise ConnectionError(err, request=request)
ConnectionError: ('Connection aborted.', error(111, 'Connection refused'))
2017-08-15 22:11:55,925 - octoprint.timelapse - ERROR - Could not capture image /home/rhradec/.octoprint/timelapse/tmp/minimalistExtruderBase06.0060.dbool_assoprador2_20170815220513-48.jpg from http://hradec.no-ip.org:5001/?action=snapshot
Traceback (most recent call last):
  File "/usr/lib/python2.7/site-packages/octoprint/timelapse.py", line 505, in _perform_capture
    r = requests.get(self._snapshot_url, stream=True)
  File "/usr/lib/python2.7/site-packages/requests/api.py", line 69, in get
    return request('get', url, params=params, **kwargs)
  File "/usr/lib/python2.7/site-packages/requests/api.py", line 50, in request
    response = session.request(method=method, url=url, **kwargs)
  File "/usr/lib/python2.7/site-packages/requests/sessions.py", line 465, in request
    resp = self.send(prep, **send_kwargs)
  File "/usr/lib/python2.7/site-packages/requests/sessions.py", line 573, in send
    r = adapter.send(request, **kwargs)
  File "/usr/lib/python2.7/site-packages/requests/adapters.py", line 415, in send
    raise ConnectionError(err, request=request)
ConnectionError: ('Connection aborted.', error(111, 'Connection refused'))
2017-08-15 22:11:55,952 - octoprint.timelapse - ERROR - Could not capture image /home/rhradec/.octoprint/timelapse/tmp/minimalistExtruderBase06.0060.dbool_assoprador2_20170815220513-49.jpg from http://hradec.no-ip.org:5001/?action=snapshot
Traceback (most recent call last):
  File "/usr/lib/python2.7/site-packages/octoprint/timelapse.py", line 505, in _perform_capture
    r = requests.get(self._snapshot_url, stream=True)
  File "/usr/lib/python2.7/site-packages/requests/api.py", line 69, in get
    return request('get', url, params=params, **kwargs)
  File "/usr/lib/python2.7/site-packages/requests/api.py", line 50, in request
    response = session.request(method=method, url=url, **kwargs)
  File "/usr/lib/python2.7/site-packages/requests/sessions.py", line 465, in request
    resp = self.send(prep, **send_kwargs)
  File "/usr/lib/python2.7/site-packages/requests/sessions.py", line 573, in send
    r = adapter.send(request, **kwargs)
  File "/usr/lib/python2.7/site-packages/requests/adapters.py", line 415, in send
    raise ConnectionError(err, request=request)
ConnectionError: ('Connection aborted.', error(111, 'Connection refused'))
2017-08-15 22:11:56,013 - octoprint.timelapse - ERROR - Could not capture image /home/rhradec/.octoprint/timelapse/tmp/minimalistExtruderBase06.0060.dbool_assoprador2_20170815220513-50.jpg from http://hradec.no-ip.org:5001/?action=snapshot
Traceback (most recent call last):
  File "/usr/lib/python2.7/site-packages/octoprint/timelapse.py", line 505, in _perform_capture
    r = requests.get(self._snapshot_url, stream=True)
  File "/usr/lib/python2.7/site-packages/requests/api.py", line 69, in get
    return request('get', url, params=params, **kwargs)
  File "/usr/lib/python2.7/site-packages/requests/api.py", line 50, in request
    response = session.request(method=method, url=url, **kwargs)
  File "/usr/lib/python2.7/site-packages/requests/sessions.py", line 465, in request
    resp = self.send(prep, **send_kwargs)
  File "/usr/lib/python2.7/site-packages/requests/sessions.py", line 573, in send
    r = adapter.send(request, **kwargs)
  File "/usr/lib/python2.7/site-packages/requests/adapters.py", line 415, in send
    raise ConnectionError(err, request=request)
ConnectionError: ('Connection aborted.', error(111, 'Connection refused'))
2017-08-15 22:11:56,033 - octoprint.timelapse - ERROR - Could not capture image /home/rhradec/.octoprint/timelapse/tmp/minimalistExtruderBase06.0060.dbool_assoprador2_20170815220513-51.jpg from http://hradec.no-ip.org:5001/?action=snapshot
Traceback (most recent call last):
  File "/usr/lib/python2.7/site-packages/octoprint/timelapse.py", line 505, in _perform_capture
    r = requests.get(self._snapshot_url, stream=True)
  File "/usr/lib/python2.7/site-packages/requests/api.py", line 69, in get
    return request('get', url, params=params, **kwargs)
  File "/usr/lib/python2.7/site-packages/requests/api.py", line 50, in request
    response = session.request(method=method, url=url, **kwargs)
  File "/usr/lib/python2.7/site-packages/requests/sessions.py", line 465, in request
    resp = self.send(prep, **send_kwargs)
  File "/usr/lib/python2.7/site-packages/requests/sessions.py", line 573, in send
    r = adapter.send(request, **kwargs)
  File "/usr/lib/python2.7/site-packages/requests/adapters.py", line 415, in send
    raise ConnectionError(err, request=request)
ConnectionError: ('Connection aborted.', error(111, 'Connection refused'))
2017-08-15 22:11:56,052 - octoprint.timelapse - ERROR - Could not capture image /home/rhradec/.octoprint/timelapse/tmp/minimalistExtruderBase06.0060.dbool_assoprador2_20170815220513-52.jpg from http://hradec.no-ip.org:5001/?action=snapshot
Traceback (most recent call last):
  File "/usr/lib/python2.7/site-packages/octoprint/timelapse.py", line 505, in _perform_capture
    r = requests.get(self._snapshot_url, stream=True)
  File "/usr/lib/python2.7/site-packages/requests/api.py", line 69, in get
    return request('get', url, params=params, **kwargs)
  File "/usr/lib/python2.7/site-packages/requests/api.py", line 50, in request
    response = session.request(method=method, url=url, **kwargs)
  File "/usr/lib/python2.7/site-packages/requests/sessions.py", line 465, in request
    resp = self.send(prep, **send_kwargs)
  File "/usr/lib/python2.7/site-packages/requests/sessions.py", line 573, in send
    r = adapter.send(request, **kwargs)
  File "/usr/lib/python2.7/site-packages/requests/adapters.py", line 415, in send
    raise ConnectionError(err, request=request)
ConnectionError: ('Connection aborted.', error(111, 'Connection refused'))
2017-08-15 22:11:56,071 - octoprint.timelapse - ERROR - Could not capture image /home/rhradec/.octoprint/timelapse/tmp/minimalistExtruderBase06.0060.dbool_assoprador2_20170815220513-53.jpg from http://hradec.no-ip.org:5001/?action=snapshot
Traceback (most recent call last):
  File "/usr/lib/python2.7/site-packages/octoprint/timelapse.py", line 505, in _perform_capture
    r = requests.get(self._snapshot_url, stream=True)
  File "/usr/lib/python2.7/site-packages/requests/api.py", line 69, in get
    return request('get', url, params=params, **kwargs)
  File "/usr/lib/python2.7/site-packages/requests/api.py", line 50, in request
    response = session.request(method=method, url=url, **kwargs)
  File "/usr/lib/python2.7/site-packages/requests/sessions.py", line 465, in request
    resp = self.send(prep, **send_kwargs)
  File "/usr/lib/python2.7/site-packages/requests/sessions.py", line 573, in send
    r = adapter.send(request, **kwargs)
  File "/usr/lib/python2.7/site-packages/requests/adapters.py", line 415, in send
    raise ConnectionError(err, request=request)
ConnectionError: ('Connection aborted.', error(111, 'Connection refused'))
2017-08-15 22:11:56,092 - octoprint.timelapse - ERROR - Could not capture image /home/rhradec/.octoprint/timelapse/tmp/minimalistExtruderBase06.0060.dbool_assoprador2_20170815220513-54.jpg from http://hradec.no-ip.org:5001/?action=snapshot
Traceback (most recent call last):
  File "/usr/lib/python2.7/site-packages/octoprint/timelapse.py", line 505, in _perform_capture
    r = requests.get(self._snapshot_url, stream=True)
  File "/usr/lib/python2.7/site-packages/requests/api.py", line 69, in get
    return request('get', url, params=params, **kwargs)
  File "/usr/lib/python2.7/site-packages/requests/api.py", line 50, in request
    response = session.request(method=method, url=url, **kwargs)
  File "/usr/lib/python2.7/site-packages/requests/sessions.py", line 465, in request
    resp = self.send(prep, **send_kwargs)
  File "/usr/lib/python2.7/site-packages/requests/sessions.py", line 573, in send
    r = adapter.send(request, **kwargs)
  File "/usr/lib/python2.7/site-packages/requests/adapters.py", line 415, in send
    raise ConnectionError(err, request=request)
ConnectionError: ('Connection aborted.', error(111, 'Connection refused'))
2017-08-15 22:11:56,120 - octoprint.timelapse - ERROR - Could not capture image /home/rhradec/.octoprint/timelapse/tmp/minimalistExtruderBase06.0060.dbool_assoprador2_20170815220513-55.jpg from http://hradec.no-ip.org:5001/?action=snapshot
Traceback (most recent call last):
  File "/usr/lib/python2.7/site-packages/octoprint/timelapse.py", line 505, in _perform_capture
    r = requests.get(self._snapshot_url, stream=True)
  File "/usr/lib/python2.7/site-packages/requests/api.py", line 69, in get
    return request('get', url, params=params, **kwargs)
  File "/usr/lib/python2.7/site-packages/requests/api.py", line 50, in request
    response = session.request(method=method, url=url, **kwargs)
  File "/usr/lib/python2.7/site-packages/requests/sessions.py", line 465, in request
    resp = self.send(prep, **send_kwargs)
  File "/usr/lib/python2.7/site-packages/requests/sessions.py", line 573, in send
    r = adapter.send(request, **kwargs)
  File "/usr/lib/python2.7/site-packages/requests/adapters.py", line 415, in send
    raise ConnectionError(err, request=request)
ConnectionError: ('Connection aborted.', error(111, 'Connection refused'))
2017-08-15 22:11:56,144 - octoprint.timelapse - ERROR - Could not capture image /home/rhradec/.octoprint/timelapse/tmp/minimalistExtruderBase06.0060.dbool_assoprador2_20170815220513-56.jpg from http://hradec.no-ip.org:5001/?action=snapshot
Traceback (most recent call last):
  File "/usr/lib/python2.7/site-packages/octoprint/timelapse.py", line 505, in _perform_capture
    r = requests.get(self._snapshot_url, stream=True)
  File "/usr/lib/python2.7/site-packages/requests/api.py", line 69, in get
    return request('get', url, params=params, **kwargs)
  File "/usr/lib/python2.7/site-packages/requests/api.py", line 50, in request
    response = session.request(method=method, url=url, **kwargs)
  File "/usr/lib/python2.7/site-packages/requests/sessions.py", line 465, in request
    resp = self.send(prep, **send_kwargs)
  File "/usr/lib/python2.7/site-packages/requests/sessions.py", line 573, in send
    r = adapter.send(request, **kwargs)
  File "/usr/lib/python2.7/site-packages/requests/adapters.py", line 415, in send
    raise ConnectionError(err, request=request)
ConnectionError: ('Connection aborted.', error(111, 'Connection refused'))
2017-08-15 22:11:56,165 - octoprint.timelapse - ERROR - Could not capture image /home/rhradec/.octoprint/timelapse/tmp/minimalistExtruderBase06.0060.dbool_assoprador2_20170815220513-57.jpg from http://hradec.no-ip.org:5001/?action=snapshot
Traceback (most recent call last):
  File "/usr/lib/python2.7/site-packages/octoprint/timelapse.py", line 505, in _perform_capture
    r = requests.get(self._snapshot_url, stream=True)
  File "/usr/lib/python2.7/site-packages/requests/api.py", line 69, in get
    return request('get', url, params=params, **kwargs)
  File "/usr/lib/python2.7/site-packages/requests/api.py", line 50, in request
    response = session.request(method=method, url=url, **kwargs)
  File "/usr/lib/python2.7/site-packages/requests/sessions.py", line 465, in request
    resp = self.send(prep, **send_kwargs)
  File "/usr/lib/python2.7/site-packages/requests/sessions.py", line 573, in send
    r = adapter.send(request, **kwargs)
  File "/usr/lib/python2.7/site-packages/requests/adapters.py", line 415, in send
    raise ConnectionError(err, request=request)
ConnectionError: ('Connection aborted.', error(111, 'Connection refused'))
2017-08-15 22:11:56,186 - octoprint.timelapse - ERROR - Could not capture image /home/rhradec/.octoprint/timelapse/tmp/minimalistExtruderBase06.0060.dbool_assoprador2_20170815220513-58.jpg from http://hradec.no-ip.org:5001/?action=snapshot
Traceback (most recent call last):
  File "/usr/lib/python2.7/site-packages/octoprint/timelapse.py", line 505, in _perform_capture
    r = requests.get(self._snapshot_url, stream=True)
  File "/usr/lib/python2.7/site-packages/requests/api.py", line 69, in get
    return request('get', url, params=params, **kwargs)
  File "/usr/lib/python2.7/site-packages/requests/api.py", line 50, in request
    response = session.request(method=method, url=url, **kwargs)
  File "/usr/lib/python2.7/site-packages/requests/sessions.py", line 465, in request
    resp = self.send(prep, **send_kwargs)
  File "/usr/lib/python2.7/site-packages/requests/sessions.py", line 573, in send
    r = adapter.send(request, **kwargs)
  File "/usr/lib/python2.7/site-packages/requests/adapters.py", line 415, in send
    raise ConnectionError(err, request=request)
ConnectionError: ('Connection aborted.', error(111, 'Connection refused'))
2017-08-15 22:11:56,207 - octoprint.timelapse - ERROR - Could not capture image /home/rhradec/.octoprint/timelapse/tmp/minimalistExtruderBase06.0060.dbool_assoprador2_20170815220513-59.jpg from http://hradec.no-ip.org:5001/?action=snapshot
Traceback (most recent call last):
  File "/usr/lib/python2.7/site-packages/octoprint/timelapse.py", line 505, in _perform_capture
    r = requests.get(self._snapshot_url, stream=True)
  File "/usr/lib/python2.7/site-packages/requests/api.py", line 69, in get
    return request('get', url, params=params, **kwargs)
  File "/usr/lib/python2.7/site-packages/requests/api.py", line 50, in request
    response = session.request(method=method, url=url, **kwargs)
  File "/usr/lib/python2.7/site-packages/requests/sessions.py", line 465, in request
    resp = self.send(prep, **send_kwargs)
  File "/usr/lib/python2.7/site-packages/requests/sessions.py", line 573, in send
    r = adapter.send(request, **kwargs)
  File "/usr/lib/python2.7/site-packages/requests/adapters.py", line 415, in send
    raise ConnectionError(err, request=request)
ConnectionError: ('Connection aborted.', error(111, 'Connection refused'))
2017-08-15 22:11:56,227 - octoprint.timelapse - ERROR - Could not capture image /home/rhradec/.octoprint/timelapse/tmp/minimalistExtruderBase06.0060.dbool_assoprador2_20170815220513-60.jpg from http://hradec.no-ip.org:5001/?action=snapshot
Traceback (most recent call last):
  File "/usr/lib/python2.7/site-packages/octoprint/timelapse.py", line 505, in _perform_capture
    r = requests.get(self._snapshot_url, stream=True)
  File "/usr/lib/python2.7/site-packages/requests/api.py", line 69, in get
    return request('get', url, params=params, **kwargs)
  File "/usr/lib/python2.7/site-packages/requests/api.py", line 50, in request
    response = session.request(method=method, url=url, **kwargs)
  File "/usr/lib/python2.7/site-packages/requests/sessions.py", line 465, in request
    resp = self.send(prep, **send_kwargs)
  File "/usr/lib/python2.7/site-packages/requests/sessions.py", line 573, in send
    r = adapter.send(request, **kwargs)
  File "/usr/lib/python2.7/site-packages/requests/adapters.py", line 415, in send
    raise ConnectionError(err, request=request)
ConnectionError: ('Connection aborted.', error(111, 'Connection refused'))
2017-08-15 22:11:56,247 - octoprint.timelapse - ERROR - Could not capture image /home/rhradec/.octoprint/timelapse/tmp/minimalistExtruderBase06.0060.dbool_assoprador2_20170815220513-61.jpg from http://hradec.no-ip.org:5001/?action=snapshot
Traceback (most recent call last):
  File "/usr/lib/python2.7/site-packages/octoprint/timelapse.py", line 505, in _perform_capture
    r = requests.get(self._snapshot_url, stream=True)
  File "/usr/lib/python2.7/site-packages/requests/api.py", line 69, in get
    return request('get', url, params=params, **kwargs)
  File "/usr/lib/python2.7/site-packages/requests/api.py", line 50, in request
    response = session.request(method=method, url=url, **kwargs)
  File "/usr/lib/python2.7/site-packages/requests/sessions.py", line 465, in request
    resp = self.send(prep, **send_kwargs)
  File "/usr/lib/python2.7/site-packages/requests/sessions.py", line 573, in send
    r = adapter.send(request, **kwargs)
  File "/usr/lib/python2.7/site-packages/requests/adapters.py", line 415, in send
    raise ConnectionError(err, request=request)
ConnectionError: ('Connection aborted.', error(111, 'Connection refused'))
2017-08-15 22:11:56,268 - octoprint.timelapse - ERROR - Could not capture image /home/rhradec/.octoprint/timelapse/tmp/minimalistExtruderBase06.0060.dbool_assoprador2_20170815220513-62.jpg from http://hradec.no-ip.org:5001/?action=snapshot
Traceback (most recent call last):
  File "/usr/lib/python2.7/site-packages/octoprint/timelapse.py", line 505, in _perform_capture
    r = requests.get(self._snapshot_url, stream=True)
  File "/usr/lib/python2.7/site-packages/requests/api.py", line 69, in get
    return request('get', url, params=params, **kwargs)
  File "/usr/lib/python2.7/site-packages/requests/api.py", line 50, in request
    response = session.request(method=method, url=url, **kwargs)
  File "/usr/lib/python2.7/site-packages/requests/sessions.py", line 465, in request
    resp = self.send(prep, **send_kwargs)
  File "/usr/lib/python2.7/site-packages/requests/sessions.py", line 573, in send
    r = adapter.send(request, **kwargs)
  File "/usr/lib/python2.7/site-packages/requests/adapters.py", line 415, in send
    raise ConnectionError(err, request=request)
ConnectionError: ('Connection aborted.', error(111, 'Connection refused'))
2017-08-15 22:11:56,294 - octoprint.timelapse - ERROR - Could not capture image /home/rhradec/.octoprint/timelapse/tmp/minimalistExtruderBase06.0060.dbool_assoprador2_20170815220513-63.jpg from http://hradec.no-ip.org:5001/?action=snapshot
Traceback (most recent call last):
  File "/usr/lib/python2.7/site-packages/octoprint/timelapse.py", line 505, in _perform_capture
    r = requests.get(self._snapshot_url, stream=True)
  File "/usr/lib/python2.7/site-packages/requests/api.py", line 69, in get
    return request('get', url, params=params, **kwargs)
  File "/usr/lib/python2.7/site-packages/requests/api.py", line 50, in request
    response = session.request(method=method, url=url, **kwargs)
  File "/usr/lib/python2.7/site-packages/requests/sessions.py", line 465, in request
    resp = self.send(prep, **send_kwargs)
  File "/usr/lib/python2.7/site-packages/requests/sessions.py", line 573, in send
    r = adapter.send(request, **kwargs)
  File "/usr/lib/python2.7/site-packages/requests/adapters.py", line 415, in send
    raise ConnectionError(err, request=request)
ConnectionError: ('Connection aborted.', error(111, 'Connection refused'))
2017-08-15 22:11:56,314 - octoprint.timelapse - ERROR - Could not capture image /home/rhradec/.octoprint/timelapse/tmp/minimalistExtruderBase06.0060.dbool_assoprador2_20170815220513-64.jpg from http://hradec.no-ip.org:5001/?action=snapshot
Traceback (most recent call last):
  File "/usr/lib/python2.7/site-packages/octoprint/timelapse.py", line 505, in _perform_capture
    r = requests.get(self._snapshot_url, stream=True)
  File "/usr/lib/python2.7/site-packages/requests/api.py", line 69, in get
    return request('get', url, params=params, **kwargs)
  File "/usr/lib/python2.7/site-packages/requests/api.py", line 50, in request
    response = session.request(method=method, url=url, **kwargs)
  File "/usr/lib/python2.7/site-packages/requests/sessions.py", line 465, in request
    resp = self.send(prep, **send_kwargs)
  File "/usr/lib/python2.7/site-packages/requests/sessions.py", line 573, in send
    r = adapter.send(request, **kwargs)
  File "/usr/lib/python2.7/site-packages/requests/adapters.py", line 415, in send
    raise ConnectionError(err, request=request)
ConnectionError: ('Connection aborted.', error(111, 'Connection refused'))
2017-08-15 22:11:56,334 - octoprint.timelapse - ERROR - Could not capture image /home/rhradec/.octoprint/timelapse/tmp/minimalistExtruderBase06.0060.dbool_assoprador2_20170815220513-65.jpg from http://hradec.no-ip.org:5001/?action=snapshot
Traceback (most recent call last):
  File "/usr/lib/python2.7/site-packages/octoprint/timelapse.py", line 505, in _perform_capture
    r = requests.get(self._snapshot_url, stream=True)
  File "/usr/lib/python2.7/site-packages/requests/api.py", line 69, in get
    return request('get', url, params=params, **kwargs)
  File "/usr/lib/python2.7/site-packages/requests/api.py", line 50, in request
    response = session.request(method=method, url=url, **kwargs)
  File "/usr/lib/python2.7/site-packages/requests/sessions.py", line 465, in request
    resp = self.send(prep, **send_kwargs)
  File "/usr/lib/python2.7/site-packages/requests/sessions.py", line 573, in send
    r = adapter.send(request, **kwargs)
  File "/usr/lib/python2.7/site-packages/requests/adapters.py", line 415, in send
    raise ConnectionError(err, request=request)
ConnectionError: ('Connection aborted.', error(111, 'Connection refused'))
2017-08-15 22:11:56,355 - octoprint.timelapse - ERROR - Could not capture image /home/rhradec/.octoprint/timelapse/tmp/minimalistExtruderBase06.0060.dbool_assoprador2_20170815220513-66.jpg from http://hradec.no-ip.org:5001/?action=snapshot
Traceback (most recent call last):
  File "/usr/lib/python2.7/site-packages/octoprint/timelapse.py", line 505, in _perform_capture
    r = requests.get(self._snapshot_url, stream=True)
  File "/usr/lib/python2.7/site-packages/requests/api.py", line 69, in get
    return request('get', url, params=params, **kwargs)
  File "/usr/lib/python2.7/site-packages/requests/api.py", line 50, in request
    response = session.request(method=method, url=url, **kwargs)
  File "/usr/lib/python2.7/site-packages/requests/sessions.py", line 465, in request
    resp = self.send(prep, **send_kwargs)
  File "/usr/lib/python2.7/site-packages/requests/sessions.py", line 573, in send
    r = adapter.send(request, **kwargs)
  File "/usr/lib/python2.7/site-packages/requests/adapters.py", line 415, in send
    raise ConnectionError(err, request=request)
ConnectionError: ('Connection aborted.', error(111, 'Connection refused'))
2017-08-15 22:11:56,374 - octoprint.timelapse - ERROR - Could not capture image /home/rhradec/.octoprint/timelapse/tmp/minimalistExtruderBase06.0060.dbool_assoprador2_20170815220513-67.jpg from http://hradec.no-ip.org:5001/?action=snapshot
Traceback (most recent call last):
  File "/usr/lib/python2.7/site-packages/octoprint/timelapse.py", line 505, in _perform_capture
    r = requests.get(self._snapshot_url, stream=True)
  File "/usr/lib/python2.7/site-packages/requests/api.py", line 69, in get
    return request('get', url, params=params, **kwargs)
  File "/usr/lib/python2.7/site-packages/requests/api.py", line 50, in request
    response = session.request(method=method, url=url, **kwargs)
  File "/usr/lib/python2.7/site-packages/requests/sessions.py", line 465, in request
    resp = self.send(prep, **send_kwargs)
  File "/usr/lib/python2.7/site-packages/requests/sessions.py", line 573, in send
    r = adapter.send(request, **kwargs)
  File "/usr/lib/python2.7/site-packages/requests/adapters.py", line 415, in send
    raise ConnectionError(err, request=request)
ConnectionError: ('Connection aborted.', error(111, 'Connection refused'))
2017-08-15 22:11:56,393 - octoprint.timelapse - ERROR - Could not capture image /home/rhradec/.octoprint/timelapse/tmp/minimalistExtruderBase06.0060.dbool_assoprador2_20170815220513-68.jpg from http://hradec.no-ip.org:5001/?action=snapshot
Traceback (most recent call last):
  File "/usr/lib/python2.7/site-packages/octoprint/timelapse.py", line 505, in _perform_capture
    r = requests.get(self._snapshot_url, stream=True)
  File "/usr/lib/python2.7/site-packages/requests/api.py", line 69, in get
    return request('get', url, params=params, **kwargs)
  File "/usr/lib/python2.7/site-packages/requests/api.py", line 50, in request
    response = session.request(method=method, url=url, **kwargs)
  File "/usr/lib/python2.7/site-packages/requests/sessions.py", line 465, in request
    resp = self.send(prep, **send_kwargs)
  File "/usr/lib/python2.7/site-packages/requests/sessions.py", line 573, in send
    r = adapter.send(request, **kwargs)
  File "/usr/lib/python2.7/site-packages/requests/adapters.py", line 415, in send
    raise ConnectionError(err, request=request)
ConnectionError: ('Connection aborted.', error(111, 'Connection refused'))
2017-08-15 22:11:56,413 - octoprint.timelapse - ERROR - Could not capture image /home/rhradec/.octoprint/timelapse/tmp/minimalistExtruderBase06.0060.dbool_assoprador2_20170815220513-69.jpg from http://hradec.no-ip.org:5001/?action=snapshot
Traceback (most recent call last):
  File "/usr/lib/python2.7/site-packages/octoprint/timelapse.py", line 505, in _perform_capture
    r = requests.get(self._snapshot_url, stream=True)
  File "/usr/lib/python2.7/site-packages/requests/api.py", line 69, in get
    return request('get', url, params=params, **kwargs)
  File "/usr/lib/python2.7/site-packages/requests/api.py", line 50, in request
    response = session.request(method=method, url=url, **kwargs)
  File "/usr/lib/python2.7/site-packages/requests/sessions.py", line 465, in request
    resp = self.send(prep, **send_kwargs)
  File "/usr/lib/python2.7/site-packages/requests/sessions.py", line 573, in send
    r = adapter.send(request, **kwargs)
  File "/usr/lib/python2.7/site-packages/requests/adapters.py", line 415, in send
    raise ConnectionError(err, request=request)
ConnectionError: ('Connection aborted.', error(111, 'Connection refused'))
2017-08-15 22:11:56,433 - octoprint.timelapse - ERROR - Could not capture image /home/rhradec/.octoprint/timelapse/tmp/minimalistExtruderBase06.0060.dbool_assoprador2_20170815220513-70.jpg from http://hradec.no-ip.org:5001/?action=snapshot
Traceback (most recent call last):
  File "/usr/lib/python2.7/site-packages/octoprint/timelapse.py", line 505, in _perform_capture
    r = requests.get(self._snapshot_url, stream=True)
  File "/usr/lib/python2.7/site-packages/requests/api.py", line 69, in get
    return request('get', url, params=params, **kwargs)
  File "/usr/lib/python2.7/site-packages/requests/api.py", line 50, in request
    response = session.request(method=method, url=url, **kwargs)
  File "/usr/lib/python2.7/site-packages/requests/sessions.py", line 465, in request
    resp = self.send(prep, **send_kwargs)
  File "/usr/lib/python2.7/site-packages/requests/sessions.py", line 573, in send
    r = adapter.send(request, **kwargs)
  File "/usr/lib/python2.7/site-packages/requests/adapters.py", line 415, in send
    raise ConnectionError(err, request=request)
ConnectionError: ('Connection aborted.', error(111, 'Connection refused'))
2017-08-15 22:11:56,453 - octoprint.timelapse - ERROR - Could not capture image /home/rhradec/.octoprint/timelapse/tmp/minimalistExtruderBase06.0060.dbool_assoprador2_20170815220513-71.jpg from http://hradec.no-ip.org:5001/?action=snapshot
Traceback (most recent call last):
  File "/usr/lib/python2.7/site-packages/octoprint/timelapse.py", line 505, in _perform_capture
    r = requests.get(self._snapshot_url, stream=True)
  File "/usr/lib/python2.7/site-packages/requests/api.py", line 69, in get
    return request('get', url, params=params, **kwargs)
  File "/usr/lib/python2.7/site-packages/requests/api.py", line 50, in request
    response = session.request(method=method, url=url, **kwargs)
  File "/usr/lib/python2.7/site-packages/requests/sessions.py", line 465, in request
    resp = self.send(prep, **send_kwargs)
  File "/usr/lib/python2.7/site-packages/requests/sessions.py", line 573, in send
    r = adapter.send(request, **kwargs)
  File "/usr/lib/python2.7/site-packages/requests/adapters.py", line 415, in send
    raise ConnectionError(err, request=request)
ConnectionError: ('Connection aborted.', error(111, 'Connection refused'))
2017-08-15 22:11:56,472 - octoprint.timelapse - ERROR - Could not capture image /home/rhradec/.octoprint/timelapse/tmp/minimalistExtruderBase06.0060.dbool_assoprador2_20170815220513-72.jpg from http://hradec.no-ip.org:5001/?action=snapshot
Traceback (most recent call last):
  File "/usr/lib/python2.7/site-packages/octoprint/timelapse.py", line 505, in _perform_capture
    r = requests.get(self._snapshot_url, stream=True)
  File "/usr/lib/python2.7/site-packages/requests/api.py", line 69, in get
    return request('get', url, params=params, **kwargs)
  File "/usr/lib/python2.7/site-packages/requests/api.py", line 50, in request
    response = session.request(method=method, url=url, **kwargs)
  File "/usr/lib/python2.7/site-packages/requests/sessions.py", line 465, in request
    resp = self.send(prep, **send_kwargs)
  File "/usr/lib/python2.7/site-packages/requests/sessions.py", line 573, in send
    r = adapter.send(request, **kwargs)
  File "/usr/lib/python2.7/site-packages/requests/adapters.py", line 415, in send
    raise ConnectionError(err, request=request)
ConnectionError: ('Connection aborted.', error(111, 'Connection refused'))
2017-08-15 22:11:56,491 - octoprint.timelapse - ERROR - Could not capture image /home/rhradec/.octoprint/timelapse/tmp/minimalistExtruderBase06.0060.dbool_assoprador2_20170815220513-73.jpg from http://hradec.no-ip.org:5001/?action=snapshot
Traceback (most recent call last):
  File "/usr/lib/python2.7/site-packages/octoprint/timelapse.py", line 505, in _perform_capture
    r = requests.get(self._snapshot_url, stream=True)
  File "/usr/lib/python2.7/site-packages/requests/api.py", line 69, in get
    return request('get', url, params=params, **kwargs)
  File "/usr/lib/python2.7/site-packages/requests/api.py", line 50, in request
    response = session.request(method=method, url=url, **kwargs)
  File "/usr/lib/python2.7/site-packages/requests/sessions.py", line 465, in request
    resp = self.send(prep, **send_kwargs)
  File "/usr/lib/python2.7/site-packages/requests/sessions.py", line 573, in send
    r = adapter.send(request, **kwargs)
  File "/usr/lib/python2.7/site-packages/requests/adapters.py", line 415, in send
    raise ConnectionError(err, request=request)
ConnectionError: ('Connection aborted.', error(111, 'Connection refused'))
2017-08-15 22:11:56,509 - octoprint.timelapse - ERROR - Could not capture image /home/rhradec/.octoprint/timelapse/tmp/minimalistExtruderBase06.0060.dbool_assoprador2_20170815220513-74.jpg from http://hradec.no-ip.org:5001/?action=snapshot
Traceback (most recent call last):
  File "/usr/lib/python2.7/site-packages/octoprint/timelapse.py", line 505, in _perform_capture
    r = requests.get(self._snapshot_url, stream=True)
  File "/usr/lib/python2.7/site-packages/requests/api.py", line 69, in get
    return request('get', url, params=params, **kwargs)
  File "/usr/lib/python2.7/site-packages/requests/api.py", line 50, in request
    response = session.request(method=method, url=url, **kwargs)
  File "/usr/lib/python2.7/site-packages/requests/sessions.py", line 465, in request
    resp = self.send(prep, **send_kwargs)
  File "/usr/lib/python2.7/site-packages/requests/sessions.py", line 573, in send
    r = adapter.send(request, **kwargs)
  File "/usr/lib/python2.7/site-packages/requests/adapters.py", line 415, in send
    raise ConnectionError(err, request=request)
ConnectionError: ('Connection aborted.', error(111, 'Connection refused'))
2017-08-15 22:11:56,528 - octoprint.timelapse - ERROR - Could not capture image /home/rhradec/.octoprint/timelapse/tmp/minimalistExtruderBase06.0060.dbool_assoprador2_20170815220513-75.jpg from http://hradec.no-ip.org:5001/?action=snapshot
Traceback (most recent call last):
  File "/usr/lib/python2.7/site-packages/octoprint/timelapse.py", line 505, in _perform_capture
    r = requests.get(self._snapshot_url, stream=True)
  File "/usr/lib/python2.7/site-packages/requests/api.py", line 69, in get
    return request('get', url, params=params, **kwargs)
  File "/usr/lib/python2.7/site-packages/requests/api.py", line 50, in request
    response = session.request(method=method, url=url, **kwargs)
  File "/usr/lib/python2.7/site-packages/requests/sessions.py", line 465, in request
    resp = self.send(prep, **send_kwargs)
  File "/usr/lib/python2.7/site-packages/requests/sessions.py", line 573, in send
    r = adapter.send(request, **kwargs)
  File "/usr/lib/python2.7/site-packages/requests/adapters.py", line 415, in send
    raise ConnectionError(err, request=request)
ConnectionError: ('Connection aborted.', error(111, 'Connection refused'))
2017-08-15 22:11:56,547 - octoprint.timelapse - ERROR - Could not capture image /home/rhradec/.octoprint/timelapse/tmp/minimalistExtruderBase06.0060.dbool_assoprador2_20170815220513-76.jpg from http://hradec.no-ip.org:5001/?action=snapshot
Traceback (most recent call last):
  File "/usr/lib/python2.7/site-packages/octoprint/timelapse.py", line 505, in _perform_capture
    r = requests.get(self._snapshot_url, stream=True)
  File "/usr/lib/python2.7/site-packages/requests/api.py", line 69, in get
    return request('get', url, params=params, **kwargs)
  File "/usr/lib/python2.7/site-packages/requests/api.py", line 50, in request
    response = session.request(method=method, url=url, **kwargs)
  File "/usr/lib/python2.7/site-packages/requests/sessions.py", line 465, in request
    resp = self.send(prep, **send_kwargs)
  File "/usr/lib/python2.7/site-packages/requests/sessions.py", line 573, in send
    r = adapter.send(request, **kwargs)
  File "/usr/lib/python2.7/site-packages/requests/adapters.py", line 415, in send
    raise ConnectionError(err, request=request)
ConnectionError: ('Connection aborted.', error(111, 'Connection refused'))
2017-08-15 22:11:56,565 - octoprint.timelapse - ERROR - Could not capture image /home/rhradec/.octoprint/timelapse/tmp/minimalistExtruderBase06.0060.dbool_assoprador2_20170815220513-77.jpg from http://hradec.no-ip.org:5001/?action=snapshot
Traceback (most recent call last):
  File "/usr/lib/python2.7/site-packages/octoprint/timelapse.py", line 505, in _perform_capture
    r = requests.get(self._snapshot_url, stream=True)
  File "/usr/lib/python2.7/site-packages/requests/api.py", line 69, in get
    return request('get', url, params=params, **kwargs)
  File "/usr/lib/python2.7/site-packages/requests/api.py", line 50, in request
    response = session.request(method=method, url=url, **kwargs)
  File "/usr/lib/python2.7/site-packages/requests/sessions.py", line 465, in request
    resp = self.send(prep, **send_kwargs)
  File "/usr/lib/python2.7/site-packages/requests/sessions.py", line 573, in send
    r = adapter.send(request, **kwargs)
  File "/usr/lib/python2.7/site-packages/requests/adapters.py", line 415, in send
    raise ConnectionError(err, request=request)
ConnectionError: ('Connection aborted.', error(111, 'Connection refused'))
2017-08-15 22:11:56,584 - octoprint.timelapse - ERROR - Could not capture image /home/rhradec/.octoprint/timelapse/tmp/minimalistExtruderBase06.0060.dbool_assoprador2_20170815220513-78.jpg from http://hradec.no-ip.org:5001/?action=snapshot
Traceback (most recent call last):
  File "/usr/lib/python2.7/site-packages/octoprint/timelapse.py", line 505, in _perform_capture
    r = requests.get(self._snapshot_url, stream=True)
  File "/usr/lib/python2.7/site-packages/requests/api.py", line 69, in get
    return request('get', url, params=params, **kwargs)
  File "/usr/lib/python2.7/site-packages/requests/api.py", line 50, in request
    response = session.request(method=method, url=url, **kwargs)
  File "/usr/lib/python2.7/site-packages/requests/sessions.py", line 465, in request
    resp = self.send(prep, **send_kwargs)
  File "/usr/lib/python2.7/site-packages/requests/sessions.py", line 573, in send
    r = adapter.send(request, **kwargs)
  File "/usr/lib/python2.7/site-packages/requests/adapters.py", line 415, in send
    raise ConnectionError(err, request=request)
ConnectionError: ('Connection aborted.', error(111, 'Connection refused'))
2017-08-15 22:11:56,605 - octoprint.timelapse - ERROR - Could not capture image /home/rhradec/.octoprint/timelapse/tmp/minimalistExtruderBase06.0060.dbool_assoprador2_20170815220513-79.jpg from http://hradec.no-ip.org:5001/?action=snapshot
Traceback (most recent call last):
  File "/usr/lib/python2.7/site-packages/octoprint/timelapse.py", line 505, in _perform_capture
    r = requests.get(self._snapshot_url, stream=True)
  File "/usr/lib/python2.7/site-packages/requests/api.py", line 69, in get
    return request('get', url, params=params, **kwargs)
  File "/usr/lib/python2.7/site-packages/requests/api.py", line 50, in request
    response = session.request(method=method, url=url, **kwargs)
  File "/usr/lib/python2.7/site-packages/requests/sessions.py", line 465, in request
    resp = self.send(prep, **send_kwargs)
  File "/usr/lib/python2.7/site-packages/requests/sessions.py", line 573, in send
    r = adapter.send(request, **kwargs)
  File "/usr/lib/python2.7/site-packages/requests/adapters.py", line 415, in send
    raise ConnectionError(err, request=request)
ConnectionError: ('Connection aborted.', error(111, 'Connection refused'))
2017-08-15 22:11:56,624 - octoprint.timelapse - ERROR - Could not capture image /home/rhradec/.octoprint/timelapse/tmp/minimalistExtruderBase06.0060.dbool_assoprador2_20170815220513-80.jpg from http://hradec.no-ip.org:5001/?action=snapshot
Traceback (most recent call last):
  File "/usr/lib/python2.7/site-packages/octoprint/timelapse.py", line 505, in _perform_capture
    r = requests.get(self._snapshot_url, stream=True)
  File "/usr/lib/python2.7/site-packages/requests/api.py", line 69, in get
    return request('get', url, params=params, **kwargs)
  File "/usr/lib/python2.7/site-packages/requests/api.py", line 50, in request
    response = session.request(method=method, url=url, **kwargs)
  File "/usr/lib/python2.7/site-packages/requests/sessions.py", line 465, in request
    resp = self.send(prep, **send_kwargs)
  File "/usr/lib/python2.7/site-packages/requests/sessions.py", line 573, in send
    r = adapter.send(request, **kwargs)
  File "/usr/lib/python2.7/site-packages/requests/adapters.py", line 415, in send
    raise ConnectionError(err, request=request)
ConnectionError: ('Connection aborted.', error(111, 'Connection refused'))
2017-08-15 22:11:58,741 - octoprint.timelapse - ERROR - Could not capture image /home/rhradec/.octoprint/timelapse/tmp/minimalistExtruderBase06.0060.dbool_assoprador2_20170815220513-0.jpg from http://hradec.no-ip.org:5001/?action=snapshot
Traceback (most recent call last):
  File "/usr/lib/python2.7/site-packages/octoprint/timelapse.py", line 505, in _perform_capture
    r = requests.get(self._snapshot_url, stream=True)
  File "/usr/lib/python2.7/site-packages/requests/api.py", line 69, in get
    return request('get', url, params=params, **kwargs)
  File "/usr/lib/python2.7/site-packages/requests/api.py", line 50, in request
    response = session.request(method=method, url=url, **kwargs)
  File "/usr/lib/python2.7/site-packages/requests/sessions.py", line 465, in request
    resp = self.send(prep, **send_kwargs)
  File "/usr/lib/python2.7/site-packages/requests/sessions.py", line 573, in send
    r = adapter.send(request, **kwargs)
  File "/usr/lib/python2.7/site-packages/requests/adapters.py", line 415, in send
    raise ConnectionError(err, request=request)
ConnectionError: ('Connection aborted.', error(111, 'Connection refused'))
2017-08-15 22:12:01,497 - tornado.general - WARNING - error on read
Traceback (most recent call last):
  File "/usr/lib/python2.7/site-packages/tornado/iostream.py", line 601, in _handle_read
    pos = self._read_to_buffer_loop()
  File "/usr/lib/python2.7/site-packages/tornado/iostream.py", line 571, in _read_to_buffer_loop
    if self._read_to_buffer() == 0:
  File "/usr/lib/python2.7/site-packages/tornado/iostream.py", line 683, in _read_to_buffer
    chunk = self.read_from_fd()
  File "/usr/lib/python2.7/site-packages/tornado/iostream.py", line 947, in read_from_fd
    chunk = self.socket.recv(self.read_chunk_size)
error: [Errno 22] Invalid argument
2017-08-15 22:12:01,517 - octoprint.server.util.sockjs - INFO - Client connection closed: 192.168.10.10
2017-08-15 22:12:13,821 - octoprint.server.util.sockjs - INFO - Client connection closed: 192.168.10.10
2017-08-15 22:12:15,815 - octoprint.server.util.sockjs - INFO - New connection from client: 192.168.10.10
2017-08-15 22:15:30,113 - octoprint.server.util.sockjs - INFO - Client connection closed: 192.168.10.10
2017-08-15 22:15:32,203 - octoprint.server.util.sockjs - INFO - New connection from client: 192.168.10.10
2017-08-15 22:16:00,302 - octoprint.server.util.sockjs - INFO - Client connection closed: 192.168.10.10
2017-08-15 22:16:02,386 - octoprint.server.util.sockjs - INFO - New connection from client: 192.168.10.10
2017-08-15 23:34:24,124 - octoprint.filemanager.analysis - INFO - Starting analysis of local:minimalistExtruderBase06.0061.dbool_connector4.gcode
2017-08-16 13:05:20,208 - octoprint.filemanager.analysis - INFO - Starting analysis of local:bike_holder.0002.print_bootleHolder3.gcode
2017-08-16 17:11:08,762 - octoprint.filemanager.analysis - INFO - Starting analysis of local:bike_holder.0003.print_bootleHolder3.gcode
